{'TIME':2022-02-04 07:39:11,306,'ADDRESS':'10.10.150.75','URL': 'http://10.10.110.13:8001/plan/hoja_ruta','TYPE':'ERROR','MODULE':'channel','MSG':{Exception while serving /plan/hoja_ruta}}
Traceback (most recent call last):
  File "C:\Users\Administrador.WIN-DUOGLHGMSST\AppData\Local\Programs\Python\Python37\lib\site-packages\waitress\channel.py", line 397, in service
    task.service()
  File "C:\Users\Administrador.WIN-DUOGLHGMSST\AppData\Local\Programs\Python\Python37\lib\site-packages\waitress\task.py", line 168, in service
    self.execute()
  File "C:\Users\Administrador.WIN-DUOGLHGMSST\AppData\Local\Programs\Python\Python37\lib\site-packages\waitress\task.py", line 434, in execute
    app_iter = self.channel.server.application(environ, start_response)
  File "C:\Users\Administrador.WIN-DUOGLHGMSST\AppData\Local\Programs\Python\Python37\lib\site-packages\flask\app.py", line 2091, in __call__
    return self.wsgi_app(environ, start_response)
  File "C:\Users\Administrador.WIN-DUOGLHGMSST\AppData\Local\Programs\Python\Python37\lib\site-packages\flask\app.py", line 2076, in wsgi_app
    response = self.handle_exception(e)
  File "C:\Users\Administrador.WIN-DUOGLHGMSST\AppData\Local\Programs\Python\Python37\lib\site-packages\flask\app.py", line 2073, in wsgi_app
    response = self.full_dispatch_request()
  File "C:\Users\Administrador.WIN-DUOGLHGMSST\AppData\Local\Programs\Python\Python37\lib\site-packages\flask\app.py", line 1518, in full_dispatch_request
    rv = self.handle_user_exception(e)
  File "C:\Users\Administrador.WIN-DUOGLHGMSST\AppData\Local\Programs\Python\Python37\lib\site-packages\flask\app.py", line 1516, in full_dispatch_request
    rv = self.dispatch_request()
  File "C:\Users\Administrador.WIN-DUOGLHGMSST\AppData\Local\Programs\Python\Python37\lib\site-packages\flask\app.py", line 1502, in dispatch_request
    return self.ensure_sync(self.view_functions[rule.endpoint])(**req.view_args)
  File "C:\xampp\htdocs\CLANAD_PY\FlaskSecurity\app\decorators.py", line 22, in secure_function
    return func(*args, **kwargs)
  File "C:\xampp\htdocs\CLANAD_PY\FlaskSecurity\app\decorators.py", line 11, in secure_function
    return func(*args, **kwargs)
  File "C:\xampp\htdocs\CLANAD_PY\FlaskSecurity\app\src\Actividad.py", line 369, in plan_actividades
    ploads = {"CCODPLA": session["paData"]["CCODPLA"], "CCODUSU": "9999"}
KeyError: 'paData'
{'TIME':2022-02-04 07:39:14,618,'ADDRESS':'10.10.150.75','URL': 'http://10.10.110.13:8001/plan/hoja_ruta','TYPE':'ERROR','MODULE':'channel','MSG':{Exception while serving /plan/hoja_ruta}}
Traceback (most recent call last):
  File "C:\Users\Administrador.WIN-DUOGLHGMSST\AppData\Local\Programs\Python\Python37\lib\site-packages\waitress\channel.py", line 397, in service
    task.service()
  File "C:\Users\Administrador.WIN-DUOGLHGMSST\AppData\Local\Programs\Python\Python37\lib\site-packages\waitress\task.py", line 168, in service
    self.execute()
  File "C:\Users\Administrador.WIN-DUOGLHGMSST\AppData\Local\Programs\Python\Python37\lib\site-packages\waitress\task.py", line 434, in execute
    app_iter = self.channel.server.application(environ, start_response)
  File "C:\Users\Administrador.WIN-DUOGLHGMSST\AppData\Local\Programs\Python\Python37\lib\site-packages\flask\app.py", line 2091, in __call__
    return self.wsgi_app(environ, start_response)
  File "C:\Users\Administrador.WIN-DUOGLHGMSST\AppData\Local\Programs\Python\Python37\lib\site-packages\flask\app.py", line 2076, in wsgi_app
    response = self.handle_exception(e)
  File "C:\Users\Administrador.WIN-DUOGLHGMSST\AppData\Local\Programs\Python\Python37\lib\site-packages\flask\app.py", line 2073, in wsgi_app
    response = self.full_dispatch_request()
  File "C:\Users\Administrador.WIN-DUOGLHGMSST\AppData\Local\Programs\Python\Python37\lib\site-packages\flask\app.py", line 1518, in full_dispatch_request
    rv = self.handle_user_exception(e)
  File "C:\Users\Administrador.WIN-DUOGLHGMSST\AppData\Local\Programs\Python\Python37\lib\site-packages\flask\app.py", line 1516, in full_dispatch_request
    rv = self.dispatch_request()
  File "C:\Users\Administrador.WIN-DUOGLHGMSST\AppData\Local\Programs\Python\Python37\lib\site-packages\flask\app.py", line 1502, in dispatch_request
    return self.ensure_sync(self.view_functions[rule.endpoint])(**req.view_args)
  File "C:\xampp\htdocs\CLANAD_PY\FlaskSecurity\app\decorators.py", line 22, in secure_function
    return func(*args, **kwargs)
  File "C:\xampp\htdocs\CLANAD_PY\FlaskSecurity\app\decorators.py", line 11, in secure_function
    return func(*args, **kwargs)
  File "C:\xampp\htdocs\CLANAD_PY\FlaskSecurity\app\src\Actividad.py", line 369, in plan_actividades
    ploads = {"CCODPLA": session["paData"]["CCODPLA"], "CCODUSU": "9999"}
KeyError: 'paData'
{'TIME':2022-02-04 08:05:41,058,'ADDRESS':'10.10.150.80','URL': 'http://10.10.110.13:8001/agregar/cie10/0','TYPE':'ERROR','MODULE':'channel','MSG':{Exception while serving /agregar/cie10/0}}
Traceback (most recent call last):
  File "C:\Users\Administrador.WIN-DUOGLHGMSST\AppData\Local\Programs\Python\Python37\lib\site-packages\waitress\channel.py", line 397, in service
    task.service()
  File "C:\Users\Administrador.WIN-DUOGLHGMSST\AppData\Local\Programs\Python\Python37\lib\site-packages\waitress\task.py", line 168, in service
    self.execute()
  File "C:\Users\Administrador.WIN-DUOGLHGMSST\AppData\Local\Programs\Python\Python37\lib\site-packages\waitress\task.py", line 434, in execute
    app_iter = self.channel.server.application(environ, start_response)
  File "C:\Users\Administrador.WIN-DUOGLHGMSST\AppData\Local\Programs\Python\Python37\lib\site-packages\flask\app.py", line 2091, in __call__
    return self.wsgi_app(environ, start_response)
  File "C:\Users\Administrador.WIN-DUOGLHGMSST\AppData\Local\Programs\Python\Python37\lib\site-packages\flask\app.py", line 2076, in wsgi_app
    response = self.handle_exception(e)
  File "C:\Users\Administrador.WIN-DUOGLHGMSST\AppData\Local\Programs\Python\Python37\lib\site-packages\flask\app.py", line 2073, in wsgi_app
    response = self.full_dispatch_request()
  File "C:\Users\Administrador.WIN-DUOGLHGMSST\AppData\Local\Programs\Python\Python37\lib\site-packages\flask\app.py", line 1518, in full_dispatch_request
    rv = self.handle_user_exception(e)
  File "C:\Users\Administrador.WIN-DUOGLHGMSST\AppData\Local\Programs\Python\Python37\lib\site-packages\flask\app.py", line 1516, in full_dispatch_request
    rv = self.dispatch_request()
  File "C:\Users\Administrador.WIN-DUOGLHGMSST\AppData\Local\Programs\Python\Python37\lib\site-packages\flask\app.py", line 1502, in dispatch_request
    return self.ensure_sync(self.view_functions[rule.endpoint])(**req.view_args)
  File "C:\xampp\htdocs\CLANAD_PY\FlaskSecurity\app\decorators.py", line 11, in secure_function
    return func(*args, **kwargs)
  File "C:\xampp\htdocs\CLANAD_PY\FlaskSecurity\app\src\Actividad.py", line 344, in agregarcie10
    if session["paCie10"] is not None:
KeyError: 'paCie10'
{'TIME':2022-02-04 08:05:43,976,'ADDRESS':'10.10.150.80','URL': 'http://10.10.110.13:8001/agregar/cie10/0','TYPE':'ERROR','MODULE':'channel','MSG':{Exception while serving /agregar/cie10/0}}
Traceback (most recent call last):
  File "C:\Users\Administrador.WIN-DUOGLHGMSST\AppData\Local\Programs\Python\Python37\lib\site-packages\waitress\channel.py", line 397, in service
    task.service()
  File "C:\Users\Administrador.WIN-DUOGLHGMSST\AppData\Local\Programs\Python\Python37\lib\site-packages\waitress\task.py", line 168, in service
    self.execute()
  File "C:\Users\Administrador.WIN-DUOGLHGMSST\AppData\Local\Programs\Python\Python37\lib\site-packages\waitress\task.py", line 434, in execute
    app_iter = self.channel.server.application(environ, start_response)
  File "C:\Users\Administrador.WIN-DUOGLHGMSST\AppData\Local\Programs\Python\Python37\lib\site-packages\flask\app.py", line 2091, in __call__
    return self.wsgi_app(environ, start_response)
  File "C:\Users\Administrador.WIN-DUOGLHGMSST\AppData\Local\Programs\Python\Python37\lib\site-packages\flask\app.py", line 2076, in wsgi_app
    response = self.handle_exception(e)
  File "C:\Users\Administrador.WIN-DUOGLHGMSST\AppData\Local\Programs\Python\Python37\lib\site-packages\flask\app.py", line 2073, in wsgi_app
    response = self.full_dispatch_request()
  File "C:\Users\Administrador.WIN-DUOGLHGMSST\AppData\Local\Programs\Python\Python37\lib\site-packages\flask\app.py", line 1518, in full_dispatch_request
    rv = self.handle_user_exception(e)
  File "C:\Users\Administrador.WIN-DUOGLHGMSST\AppData\Local\Programs\Python\Python37\lib\site-packages\flask\app.py", line 1516, in full_dispatch_request
    rv = self.dispatch_request()
  File "C:\Users\Administrador.WIN-DUOGLHGMSST\AppData\Local\Programs\Python\Python37\lib\site-packages\flask\app.py", line 1502, in dispatch_request
    return self.ensure_sync(self.view_functions[rule.endpoint])(**req.view_args)
  File "C:\xampp\htdocs\CLANAD_PY\FlaskSecurity\app\decorators.py", line 11, in secure_function
    return func(*args, **kwargs)
  File "C:\xampp\htdocs\CLANAD_PY\FlaskSecurity\app\src\Actividad.py", line 344, in agregarcie10
    if session["paCie10"] is not None:
KeyError: 'paCie10'
{'TIME':2022-02-04 08:05:48,336,'ADDRESS':'10.10.150.80','URL': 'http://10.10.110.13:8001/agregar/cie10/0','TYPE':'ERROR','MODULE':'channel','MSG':{Exception while serving /agregar/cie10/0}}
Traceback (most recent call last):
  File "C:\Users\Administrador.WIN-DUOGLHGMSST\AppData\Local\Programs\Python\Python37\lib\site-packages\waitress\channel.py", line 397, in service
    task.service()
  File "C:\Users\Administrador.WIN-DUOGLHGMSST\AppData\Local\Programs\Python\Python37\lib\site-packages\waitress\task.py", line 168, in service
    self.execute()
  File "C:\Users\Administrador.WIN-DUOGLHGMSST\AppData\Local\Programs\Python\Python37\lib\site-packages\waitress\task.py", line 434, in execute
    app_iter = self.channel.server.application(environ, start_response)
  File "C:\Users\Administrador.WIN-DUOGLHGMSST\AppData\Local\Programs\Python\Python37\lib\site-packages\flask\app.py", line 2091, in __call__
    return self.wsgi_app(environ, start_response)
  File "C:\Users\Administrador.WIN-DUOGLHGMSST\AppData\Local\Programs\Python\Python37\lib\site-packages\flask\app.py", line 2076, in wsgi_app
    response = self.handle_exception(e)
  File "C:\Users\Administrador.WIN-DUOGLHGMSST\AppData\Local\Programs\Python\Python37\lib\site-packages\flask\app.py", line 2073, in wsgi_app
    response = self.full_dispatch_request()
  File "C:\Users\Administrador.WIN-DUOGLHGMSST\AppData\Local\Programs\Python\Python37\lib\site-packages\flask\app.py", line 1518, in full_dispatch_request
    rv = self.handle_user_exception(e)
  File "C:\Users\Administrador.WIN-DUOGLHGMSST\AppData\Local\Programs\Python\Python37\lib\site-packages\flask\app.py", line 1516, in full_dispatch_request
    rv = self.dispatch_request()
  File "C:\Users\Administrador.WIN-DUOGLHGMSST\AppData\Local\Programs\Python\Python37\lib\site-packages\flask\app.py", line 1502, in dispatch_request
    return self.ensure_sync(self.view_functions[rule.endpoint])(**req.view_args)
  File "C:\xampp\htdocs\CLANAD_PY\FlaskSecurity\app\decorators.py", line 11, in secure_function
    return func(*args, **kwargs)
  File "C:\xampp\htdocs\CLANAD_PY\FlaskSecurity\app\src\Actividad.py", line 344, in agregarcie10
    if session["paCie10"] is not None:
KeyError: 'paCie10'
{'TIME':2022-02-04 08:05:49,912,'ADDRESS':'10.10.150.80','URL': 'http://10.10.110.13:8001/agregar/cie10/0','TYPE':'ERROR','MODULE':'channel','MSG':{Exception while serving /agregar/cie10/0}}
Traceback (most recent call last):
  File "C:\Users\Administrador.WIN-DUOGLHGMSST\AppData\Local\Programs\Python\Python37\lib\site-packages\waitress\channel.py", line 397, in service
    task.service()
  File "C:\Users\Administrador.WIN-DUOGLHGMSST\AppData\Local\Programs\Python\Python37\lib\site-packages\waitress\task.py", line 168, in service
    self.execute()
  File "C:\Users\Administrador.WIN-DUOGLHGMSST\AppData\Local\Programs\Python\Python37\lib\site-packages\waitress\task.py", line 434, in execute
    app_iter = self.channel.server.application(environ, start_response)
  File "C:\Users\Administrador.WIN-DUOGLHGMSST\AppData\Local\Programs\Python\Python37\lib\site-packages\flask\app.py", line 2091, in __call__
    return self.wsgi_app(environ, start_response)
  File "C:\Users\Administrador.WIN-DUOGLHGMSST\AppData\Local\Programs\Python\Python37\lib\site-packages\flask\app.py", line 2076, in wsgi_app
    response = self.handle_exception(e)
  File "C:\Users\Administrador.WIN-DUOGLHGMSST\AppData\Local\Programs\Python\Python37\lib\site-packages\flask\app.py", line 2073, in wsgi_app
    response = self.full_dispatch_request()
  File "C:\Users\Administrador.WIN-DUOGLHGMSST\AppData\Local\Programs\Python\Python37\lib\site-packages\flask\app.py", line 1518, in full_dispatch_request
    rv = self.handle_user_exception(e)
  File "C:\Users\Administrador.WIN-DUOGLHGMSST\AppData\Local\Programs\Python\Python37\lib\site-packages\flask\app.py", line 1516, in full_dispatch_request
    rv = self.dispatch_request()
  File "C:\Users\Administrador.WIN-DUOGLHGMSST\AppData\Local\Programs\Python\Python37\lib\site-packages\flask\app.py", line 1502, in dispatch_request
    return self.ensure_sync(self.view_functions[rule.endpoint])(**req.view_args)
  File "C:\xampp\htdocs\CLANAD_PY\FlaskSecurity\app\decorators.py", line 11, in secure_function
    return func(*args, **kwargs)
  File "C:\xampp\htdocs\CLANAD_PY\FlaskSecurity\app\src\Actividad.py", line 344, in agregarcie10
    if session["paCie10"] is not None:
KeyError: 'paCie10'
{'TIME':2022-02-04 08:05:53,168,'ADDRESS':'10.10.150.80','URL': 'http://10.10.110.13:8001/agregar/cie10/0','TYPE':'ERROR','MODULE':'channel','MSG':{Exception while serving /agregar/cie10/0}}
Traceback (most recent call last):
  File "C:\Users\Administrador.WIN-DUOGLHGMSST\AppData\Local\Programs\Python\Python37\lib\site-packages\waitress\channel.py", line 397, in service
    task.service()
  File "C:\Users\Administrador.WIN-DUOGLHGMSST\AppData\Local\Programs\Python\Python37\lib\site-packages\waitress\task.py", line 168, in service
    self.execute()
  File "C:\Users\Administrador.WIN-DUOGLHGMSST\AppData\Local\Programs\Python\Python37\lib\site-packages\waitress\task.py", line 434, in execute
    app_iter = self.channel.server.application(environ, start_response)
  File "C:\Users\Administrador.WIN-DUOGLHGMSST\AppData\Local\Programs\Python\Python37\lib\site-packages\flask\app.py", line 2091, in __call__
    return self.wsgi_app(environ, start_response)
  File "C:\Users\Administrador.WIN-DUOGLHGMSST\AppData\Local\Programs\Python\Python37\lib\site-packages\flask\app.py", line 2076, in wsgi_app
    response = self.handle_exception(e)
  File "C:\Users\Administrador.WIN-DUOGLHGMSST\AppData\Local\Programs\Python\Python37\lib\site-packages\flask\app.py", line 2073, in wsgi_app
    response = self.full_dispatch_request()
  File "C:\Users\Administrador.WIN-DUOGLHGMSST\AppData\Local\Programs\Python\Python37\lib\site-packages\flask\app.py", line 1518, in full_dispatch_request
    rv = self.handle_user_exception(e)
  File "C:\Users\Administrador.WIN-DUOGLHGMSST\AppData\Local\Programs\Python\Python37\lib\site-packages\flask\app.py", line 1516, in full_dispatch_request
    rv = self.dispatch_request()
  File "C:\Users\Administrador.WIN-DUOGLHGMSST\AppData\Local\Programs\Python\Python37\lib\site-packages\flask\app.py", line 1502, in dispatch_request
    return self.ensure_sync(self.view_functions[rule.endpoint])(**req.view_args)
  File "C:\xampp\htdocs\CLANAD_PY\FlaskSecurity\app\decorators.py", line 11, in secure_function
    return func(*args, **kwargs)
  File "C:\xampp\htdocs\CLANAD_PY\FlaskSecurity\app\src\Actividad.py", line 344, in agregarcie10
    if session["paCie10"] is not None:
KeyError: 'paCie10'
{'TIME':2022-02-04 08:05:57,496,'ADDRESS':'10.10.150.80','URL': 'http://10.10.110.13:8001/agregar/cie10/0','TYPE':'ERROR','MODULE':'channel','MSG':{Exception while serving /agregar/cie10/0}}
Traceback (most recent call last):
  File "C:\Users\Administrador.WIN-DUOGLHGMSST\AppData\Local\Programs\Python\Python37\lib\site-packages\waitress\channel.py", line 397, in service
    task.service()
  File "C:\Users\Administrador.WIN-DUOGLHGMSST\AppData\Local\Programs\Python\Python37\lib\site-packages\waitress\task.py", line 168, in service
    self.execute()
  File "C:\Users\Administrador.WIN-DUOGLHGMSST\AppData\Local\Programs\Python\Python37\lib\site-packages\waitress\task.py", line 434, in execute
    app_iter = self.channel.server.application(environ, start_response)
  File "C:\Users\Administrador.WIN-DUOGLHGMSST\AppData\Local\Programs\Python\Python37\lib\site-packages\flask\app.py", line 2091, in __call__
    return self.wsgi_app(environ, start_response)
  File "C:\Users\Administrador.WIN-DUOGLHGMSST\AppData\Local\Programs\Python\Python37\lib\site-packages\flask\app.py", line 2076, in wsgi_app
    response = self.handle_exception(e)
  File "C:\Users\Administrador.WIN-DUOGLHGMSST\AppData\Local\Programs\Python\Python37\lib\site-packages\flask\app.py", line 2073, in wsgi_app
    response = self.full_dispatch_request()
  File "C:\Users\Administrador.WIN-DUOGLHGMSST\AppData\Local\Programs\Python\Python37\lib\site-packages\flask\app.py", line 1518, in full_dispatch_request
    rv = self.handle_user_exception(e)
  File "C:\Users\Administrador.WIN-DUOGLHGMSST\AppData\Local\Programs\Python\Python37\lib\site-packages\flask\app.py", line 1516, in full_dispatch_request
    rv = self.dispatch_request()
  File "C:\Users\Administrador.WIN-DUOGLHGMSST\AppData\Local\Programs\Python\Python37\lib\site-packages\flask\app.py", line 1502, in dispatch_request
    return self.ensure_sync(self.view_functions[rule.endpoint])(**req.view_args)
  File "C:\xampp\htdocs\CLANAD_PY\FlaskSecurity\app\decorators.py", line 11, in secure_function
    return func(*args, **kwargs)
  File "C:\xampp\htdocs\CLANAD_PY\FlaskSecurity\app\src\Actividad.py", line 344, in agregarcie10
    if session["paCie10"] is not None:
KeyError: 'paCie10'
{'TIME':2022-02-04 08:06:27,752,'ADDRESS':'10.10.150.80','URL': 'http://10.10.110.13:8001/agregar/cie10/0','TYPE':'ERROR','MODULE':'channel','MSG':{Exception while serving /agregar/cie10/0}}
Traceback (most recent call last):
  File "C:\Users\Administrador.WIN-DUOGLHGMSST\AppData\Local\Programs\Python\Python37\lib\site-packages\waitress\channel.py", line 397, in service
    task.service()
  File "C:\Users\Administrador.WIN-DUOGLHGMSST\AppData\Local\Programs\Python\Python37\lib\site-packages\waitress\task.py", line 168, in service
    self.execute()
  File "C:\Users\Administrador.WIN-DUOGLHGMSST\AppData\Local\Programs\Python\Python37\lib\site-packages\waitress\task.py", line 434, in execute
    app_iter = self.channel.server.application(environ, start_response)
  File "C:\Users\Administrador.WIN-DUOGLHGMSST\AppData\Local\Programs\Python\Python37\lib\site-packages\flask\app.py", line 2091, in __call__
    return self.wsgi_app(environ, start_response)
  File "C:\Users\Administrador.WIN-DUOGLHGMSST\AppData\Local\Programs\Python\Python37\lib\site-packages\flask\app.py", line 2076, in wsgi_app
    response = self.handle_exception(e)
  File "C:\Users\Administrador.WIN-DUOGLHGMSST\AppData\Local\Programs\Python\Python37\lib\site-packages\flask\app.py", line 2073, in wsgi_app
    response = self.full_dispatch_request()
  File "C:\Users\Administrador.WIN-DUOGLHGMSST\AppData\Local\Programs\Python\Python37\lib\site-packages\flask\app.py", line 1518, in full_dispatch_request
    rv = self.handle_user_exception(e)
  File "C:\Users\Administrador.WIN-DUOGLHGMSST\AppData\Local\Programs\Python\Python37\lib\site-packages\flask\app.py", line 1516, in full_dispatch_request
    rv = self.dispatch_request()
  File "C:\Users\Administrador.WIN-DUOGLHGMSST\AppData\Local\Programs\Python\Python37\lib\site-packages\flask\app.py", line 1502, in dispatch_request
    return self.ensure_sync(self.view_functions[rule.endpoint])(**req.view_args)
  File "C:\xampp\htdocs\CLANAD_PY\FlaskSecurity\app\decorators.py", line 11, in secure_function
    return func(*args, **kwargs)
  File "C:\xampp\htdocs\CLANAD_PY\FlaskSecurity\app\src\Actividad.py", line 344, in agregarcie10
    if session["paCie10"] is not None:
KeyError: 'paCie10'
{'TIME':2022-02-04 08:06:37,192,'ADDRESS':'10.10.150.80','URL': 'http://10.10.110.13:8001/agregar/cie10/0','TYPE':'ERROR','MODULE':'channel','MSG':{Exception while serving /agregar/cie10/0}}
Traceback (most recent call last):
  File "C:\Users\Administrador.WIN-DUOGLHGMSST\AppData\Local\Programs\Python\Python37\lib\site-packages\waitress\channel.py", line 397, in service
    task.service()
  File "C:\Users\Administrador.WIN-DUOGLHGMSST\AppData\Local\Programs\Python\Python37\lib\site-packages\waitress\task.py", line 168, in service
    self.execute()
  File "C:\Users\Administrador.WIN-DUOGLHGMSST\AppData\Local\Programs\Python\Python37\lib\site-packages\waitress\task.py", line 434, in execute
    app_iter = self.channel.server.application(environ, start_response)
  File "C:\Users\Administrador.WIN-DUOGLHGMSST\AppData\Local\Programs\Python\Python37\lib\site-packages\flask\app.py", line 2091, in __call__
    return self.wsgi_app(environ, start_response)
  File "C:\Users\Administrador.WIN-DUOGLHGMSST\AppData\Local\Programs\Python\Python37\lib\site-packages\flask\app.py", line 2076, in wsgi_app
    response = self.handle_exception(e)
  File "C:\Users\Administrador.WIN-DUOGLHGMSST\AppData\Local\Programs\Python\Python37\lib\site-packages\flask\app.py", line 2073, in wsgi_app
    response = self.full_dispatch_request()
  File "C:\Users\Administrador.WIN-DUOGLHGMSST\AppData\Local\Programs\Python\Python37\lib\site-packages\flask\app.py", line 1518, in full_dispatch_request
    rv = self.handle_user_exception(e)
  File "C:\Users\Administrador.WIN-DUOGLHGMSST\AppData\Local\Programs\Python\Python37\lib\site-packages\flask\app.py", line 1516, in full_dispatch_request
    rv = self.dispatch_request()
  File "C:\Users\Administrador.WIN-DUOGLHGMSST\AppData\Local\Programs\Python\Python37\lib\site-packages\flask\app.py", line 1502, in dispatch_request
    return self.ensure_sync(self.view_functions[rule.endpoint])(**req.view_args)
  File "C:\xampp\htdocs\CLANAD_PY\FlaskSecurity\app\decorators.py", line 11, in secure_function
    return func(*args, **kwargs)
  File "C:\xampp\htdocs\CLANAD_PY\FlaskSecurity\app\src\Actividad.py", line 344, in agregarcie10
    if session["paCie10"] is not None:
KeyError: 'paCie10'
{'TIME':2022-02-04 08:11:02,792,'ADDRESS':'10.10.150.80','URL': 'http://10.10.110.13:8001/agregar/cie10/0','TYPE':'ERROR','MODULE':'channel','MSG':{Exception while serving /agregar/cie10/0}}
Traceback (most recent call last):
  File "C:\Users\Administrador.WIN-DUOGLHGMSST\AppData\Local\Programs\Python\Python37\lib\site-packages\waitress\channel.py", line 397, in service
    task.service()
  File "C:\Users\Administrador.WIN-DUOGLHGMSST\AppData\Local\Programs\Python\Python37\lib\site-packages\waitress\task.py", line 168, in service
    self.execute()
  File "C:\Users\Administrador.WIN-DUOGLHGMSST\AppData\Local\Programs\Python\Python37\lib\site-packages\waitress\task.py", line 434, in execute
    app_iter = self.channel.server.application(environ, start_response)
  File "C:\Users\Administrador.WIN-DUOGLHGMSST\AppData\Local\Programs\Python\Python37\lib\site-packages\flask\app.py", line 2091, in __call__
    return self.wsgi_app(environ, start_response)
  File "C:\Users\Administrador.WIN-DUOGLHGMSST\AppData\Local\Programs\Python\Python37\lib\site-packages\flask\app.py", line 2076, in wsgi_app
    response = self.handle_exception(e)
  File "C:\Users\Administrador.WIN-DUOGLHGMSST\AppData\Local\Programs\Python\Python37\lib\site-packages\flask\app.py", line 2073, in wsgi_app
    response = self.full_dispatch_request()
  File "C:\Users\Administrador.WIN-DUOGLHGMSST\AppData\Local\Programs\Python\Python37\lib\site-packages\flask\app.py", line 1518, in full_dispatch_request
    rv = self.handle_user_exception(e)
  File "C:\Users\Administrador.WIN-DUOGLHGMSST\AppData\Local\Programs\Python\Python37\lib\site-packages\flask\app.py", line 1516, in full_dispatch_request
    rv = self.dispatch_request()
  File "C:\Users\Administrador.WIN-DUOGLHGMSST\AppData\Local\Programs\Python\Python37\lib\site-packages\flask\app.py", line 1502, in dispatch_request
    return self.ensure_sync(self.view_functions[rule.endpoint])(**req.view_args)
  File "C:\xampp\htdocs\CLANAD_PY\FlaskSecurity\app\decorators.py", line 11, in secure_function
    return func(*args, **kwargs)
  File "C:\xampp\htdocs\CLANAD_PY\FlaskSecurity\app\src\Actividad.py", line 344, in agregarcie10
    if session["paCie10"] is not None:
KeyError: 'paCie10'
{'TIME':2022-02-04 08:11:04,957,'ADDRESS':'10.10.150.80','URL': 'http://10.10.110.13:8001/agregar/cie10/0','TYPE':'ERROR','MODULE':'channel','MSG':{Exception while serving /agregar/cie10/0}}
Traceback (most recent call last):
  File "C:\Users\Administrador.WIN-DUOGLHGMSST\AppData\Local\Programs\Python\Python37\lib\site-packages\waitress\channel.py", line 397, in service
    task.service()
  File "C:\Users\Administrador.WIN-DUOGLHGMSST\AppData\Local\Programs\Python\Python37\lib\site-packages\waitress\task.py", line 168, in service
    self.execute()
  File "C:\Users\Administrador.WIN-DUOGLHGMSST\AppData\Local\Programs\Python\Python37\lib\site-packages\waitress\task.py", line 434, in execute
    app_iter = self.channel.server.application(environ, start_response)
  File "C:\Users\Administrador.WIN-DUOGLHGMSST\AppData\Local\Programs\Python\Python37\lib\site-packages\flask\app.py", line 2091, in __call__
    return self.wsgi_app(environ, start_response)
  File "C:\Users\Administrador.WIN-DUOGLHGMSST\AppData\Local\Programs\Python\Python37\lib\site-packages\flask\app.py", line 2076, in wsgi_app
    response = self.handle_exception(e)
  File "C:\Users\Administrador.WIN-DUOGLHGMSST\AppData\Local\Programs\Python\Python37\lib\site-packages\flask\app.py", line 2073, in wsgi_app
    response = self.full_dispatch_request()
  File "C:\Users\Administrador.WIN-DUOGLHGMSST\AppData\Local\Programs\Python\Python37\lib\site-packages\flask\app.py", line 1518, in full_dispatch_request
    rv = self.handle_user_exception(e)
  File "C:\Users\Administrador.WIN-DUOGLHGMSST\AppData\Local\Programs\Python\Python37\lib\site-packages\flask\app.py", line 1516, in full_dispatch_request
    rv = self.dispatch_request()
  File "C:\Users\Administrador.WIN-DUOGLHGMSST\AppData\Local\Programs\Python\Python37\lib\site-packages\flask\app.py", line 1502, in dispatch_request
    return self.ensure_sync(self.view_functions[rule.endpoint])(**req.view_args)
  File "C:\xampp\htdocs\CLANAD_PY\FlaskSecurity\app\decorators.py", line 11, in secure_function
    return func(*args, **kwargs)
  File "C:\xampp\htdocs\CLANAD_PY\FlaskSecurity\app\src\Actividad.py", line 344, in agregarcie10
    if session["paCie10"] is not None:
KeyError: 'paCie10'
{'TIME':2022-02-04 08:11:06,126,'ADDRESS':'10.10.150.80','URL': 'http://10.10.110.13:8001/agregar/cie10/0','TYPE':'ERROR','MODULE':'channel','MSG':{Exception while serving /agregar/cie10/0}}
Traceback (most recent call last):
  File "C:\Users\Administrador.WIN-DUOGLHGMSST\AppData\Local\Programs\Python\Python37\lib\site-packages\waitress\channel.py", line 397, in service
    task.service()
  File "C:\Users\Administrador.WIN-DUOGLHGMSST\AppData\Local\Programs\Python\Python37\lib\site-packages\waitress\task.py", line 168, in service
    self.execute()
  File "C:\Users\Administrador.WIN-DUOGLHGMSST\AppData\Local\Programs\Python\Python37\lib\site-packages\waitress\task.py", line 434, in execute
    app_iter = self.channel.server.application(environ, start_response)
  File "C:\Users\Administrador.WIN-DUOGLHGMSST\AppData\Local\Programs\Python\Python37\lib\site-packages\flask\app.py", line 2091, in __call__
    return self.wsgi_app(environ, start_response)
  File "C:\Users\Administrador.WIN-DUOGLHGMSST\AppData\Local\Programs\Python\Python37\lib\site-packages\flask\app.py", line 2076, in wsgi_app
    response = self.handle_exception(e)
  File "C:\Users\Administrador.WIN-DUOGLHGMSST\AppData\Local\Programs\Python\Python37\lib\site-packages\flask\app.py", line 2073, in wsgi_app
    response = self.full_dispatch_request()
  File "C:\Users\Administrador.WIN-DUOGLHGMSST\AppData\Local\Programs\Python\Python37\lib\site-packages\flask\app.py", line 1518, in full_dispatch_request
    rv = self.handle_user_exception(e)
  File "C:\Users\Administrador.WIN-DUOGLHGMSST\AppData\Local\Programs\Python\Python37\lib\site-packages\flask\app.py", line 1516, in full_dispatch_request
    rv = self.dispatch_request()
  File "C:\Users\Administrador.WIN-DUOGLHGMSST\AppData\Local\Programs\Python\Python37\lib\site-packages\flask\app.py", line 1502, in dispatch_request
    return self.ensure_sync(self.view_functions[rule.endpoint])(**req.view_args)
  File "C:\xampp\htdocs\CLANAD_PY\FlaskSecurity\app\decorators.py", line 11, in secure_function
    return func(*args, **kwargs)
  File "C:\xampp\htdocs\CLANAD_PY\FlaskSecurity\app\src\Actividad.py", line 344, in agregarcie10
    if session["paCie10"] is not None:
KeyError: 'paCie10'
{'TIME':2022-02-04 08:11:06,301,'ADDRESS':'10.10.150.80','URL': 'http://10.10.110.13:8001/agregar/cie10/0','TYPE':'ERROR','MODULE':'channel','MSG':{Exception while serving /agregar/cie10/0}}
Traceback (most recent call last):
  File "C:\Users\Administrador.WIN-DUOGLHGMSST\AppData\Local\Programs\Python\Python37\lib\site-packages\waitress\channel.py", line 397, in service
    task.service()
  File "C:\Users\Administrador.WIN-DUOGLHGMSST\AppData\Local\Programs\Python\Python37\lib\site-packages\waitress\task.py", line 168, in service
    self.execute()
  File "C:\Users\Administrador.WIN-DUOGLHGMSST\AppData\Local\Programs\Python\Python37\lib\site-packages\waitress\task.py", line 434, in execute
    app_iter = self.channel.server.application(environ, start_response)
  File "C:\Users\Administrador.WIN-DUOGLHGMSST\AppData\Local\Programs\Python\Python37\lib\site-packages\flask\app.py", line 2091, in __call__
    return self.wsgi_app(environ, start_response)
  File "C:\Users\Administrador.WIN-DUOGLHGMSST\AppData\Local\Programs\Python\Python37\lib\site-packages\flask\app.py", line 2076, in wsgi_app
    response = self.handle_exception(e)
  File "C:\Users\Administrador.WIN-DUOGLHGMSST\AppData\Local\Programs\Python\Python37\lib\site-packages\flask\app.py", line 2073, in wsgi_app
    response = self.full_dispatch_request()
  File "C:\Users\Administrador.WIN-DUOGLHGMSST\AppData\Local\Programs\Python\Python37\lib\site-packages\flask\app.py", line 1518, in full_dispatch_request
    rv = self.handle_user_exception(e)
  File "C:\Users\Administrador.WIN-DUOGLHGMSST\AppData\Local\Programs\Python\Python37\lib\site-packages\flask\app.py", line 1516, in full_dispatch_request
    rv = self.dispatch_request()
  File "C:\Users\Administrador.WIN-DUOGLHGMSST\AppData\Local\Programs\Python\Python37\lib\site-packages\flask\app.py", line 1502, in dispatch_request
    return self.ensure_sync(self.view_functions[rule.endpoint])(**req.view_args)
  File "C:\xampp\htdocs\CLANAD_PY\FlaskSecurity\app\decorators.py", line 11, in secure_function
    return func(*args, **kwargs)
  File "C:\xampp\htdocs\CLANAD_PY\FlaskSecurity\app\src\Actividad.py", line 344, in agregarcie10
    if session["paCie10"] is not None:
KeyError: 'paCie10'
{'TIME':2022-02-04 08:11:06,461,'ADDRESS':'10.10.150.80','URL': 'http://10.10.110.13:8001/agregar/cie10/0','TYPE':'ERROR','MODULE':'channel','MSG':{Exception while serving /agregar/cie10/0}}
Traceback (most recent call last):
  File "C:\Users\Administrador.WIN-DUOGLHGMSST\AppData\Local\Programs\Python\Python37\lib\site-packages\waitress\channel.py", line 397, in service
    task.service()
  File "C:\Users\Administrador.WIN-DUOGLHGMSST\AppData\Local\Programs\Python\Python37\lib\site-packages\waitress\task.py", line 168, in service
    self.execute()
  File "C:\Users\Administrador.WIN-DUOGLHGMSST\AppData\Local\Programs\Python\Python37\lib\site-packages\waitress\task.py", line 434, in execute
    app_iter = self.channel.server.application(environ, start_response)
  File "C:\Users\Administrador.WIN-DUOGLHGMSST\AppData\Local\Programs\Python\Python37\lib\site-packages\flask\app.py", line 2091, in __call__
    return self.wsgi_app(environ, start_response)
  File "C:\Users\Administrador.WIN-DUOGLHGMSST\AppData\Local\Programs\Python\Python37\lib\site-packages\flask\app.py", line 2076, in wsgi_app
    response = self.handle_exception(e)
  File "C:\Users\Administrador.WIN-DUOGLHGMSST\AppData\Local\Programs\Python\Python37\lib\site-packages\flask\app.py", line 2073, in wsgi_app
    response = self.full_dispatch_request()
  File "C:\Users\Administrador.WIN-DUOGLHGMSST\AppData\Local\Programs\Python\Python37\lib\site-packages\flask\app.py", line 1518, in full_dispatch_request
    rv = self.handle_user_exception(e)
  File "C:\Users\Administrador.WIN-DUOGLHGMSST\AppData\Local\Programs\Python\Python37\lib\site-packages\flask\app.py", line 1516, in full_dispatch_request
    rv = self.dispatch_request()
  File "C:\Users\Administrador.WIN-DUOGLHGMSST\AppData\Local\Programs\Python\Python37\lib\site-packages\flask\app.py", line 1502, in dispatch_request
    return self.ensure_sync(self.view_functions[rule.endpoint])(**req.view_args)
  File "C:\xampp\htdocs\CLANAD_PY\FlaskSecurity\app\decorators.py", line 11, in secure_function
    return func(*args, **kwargs)
  File "C:\xampp\htdocs\CLANAD_PY\FlaskSecurity\app\src\Actividad.py", line 344, in agregarcie10
    if session["paCie10"] is not None:
KeyError: 'paCie10'
{'TIME':2022-02-04 08:11:06,614,'ADDRESS':'10.10.150.80','URL': 'http://10.10.110.13:8001/agregar/cie10/0','TYPE':'ERROR','MODULE':'channel','MSG':{Exception while serving /agregar/cie10/0}}
Traceback (most recent call last):
  File "C:\Users\Administrador.WIN-DUOGLHGMSST\AppData\Local\Programs\Python\Python37\lib\site-packages\waitress\channel.py", line 397, in service
    task.service()
  File "C:\Users\Administrador.WIN-DUOGLHGMSST\AppData\Local\Programs\Python\Python37\lib\site-packages\waitress\task.py", line 168, in service
    self.execute()
  File "C:\Users\Administrador.WIN-DUOGLHGMSST\AppData\Local\Programs\Python\Python37\lib\site-packages\waitress\task.py", line 434, in execute
    app_iter = self.channel.server.application(environ, start_response)
  File "C:\Users\Administrador.WIN-DUOGLHGMSST\AppData\Local\Programs\Python\Python37\lib\site-packages\flask\app.py", line 2091, in __call__
    return self.wsgi_app(environ, start_response)
  File "C:\Users\Administrador.WIN-DUOGLHGMSST\AppData\Local\Programs\Python\Python37\lib\site-packages\flask\app.py", line 2076, in wsgi_app
    response = self.handle_exception(e)
  File "C:\Users\Administrador.WIN-DUOGLHGMSST\AppData\Local\Programs\Python\Python37\lib\site-packages\flask\app.py", line 2073, in wsgi_app
    response = self.full_dispatch_request()
  File "C:\Users\Administrador.WIN-DUOGLHGMSST\AppData\Local\Programs\Python\Python37\lib\site-packages\flask\app.py", line 1518, in full_dispatch_request
    rv = self.handle_user_exception(e)
  File "C:\Users\Administrador.WIN-DUOGLHGMSST\AppData\Local\Programs\Python\Python37\lib\site-packages\flask\app.py", line 1516, in full_dispatch_request
    rv = self.dispatch_request()
  File "C:\Users\Administrador.WIN-DUOGLHGMSST\AppData\Local\Programs\Python\Python37\lib\site-packages\flask\app.py", line 1502, in dispatch_request
    return self.ensure_sync(self.view_functions[rule.endpoint])(**req.view_args)
  File "C:\xampp\htdocs\CLANAD_PY\FlaskSecurity\app\decorators.py", line 11, in secure_function
    return func(*args, **kwargs)
  File "C:\xampp\htdocs\CLANAD_PY\FlaskSecurity\app\src\Actividad.py", line 344, in agregarcie10
    if session["paCie10"] is not None:
KeyError: 'paCie10'
{'TIME':2022-02-04 08:11:06,757,'ADDRESS':'10.10.150.80','URL': 'http://10.10.110.13:8001/agregar/cie10/0','TYPE':'ERROR','MODULE':'channel','MSG':{Exception while serving /agregar/cie10/0}}
Traceback (most recent call last):
  File "C:\Users\Administrador.WIN-DUOGLHGMSST\AppData\Local\Programs\Python\Python37\lib\site-packages\waitress\channel.py", line 397, in service
    task.service()
  File "C:\Users\Administrador.WIN-DUOGLHGMSST\AppData\Local\Programs\Python\Python37\lib\site-packages\waitress\task.py", line 168, in service
    self.execute()
  File "C:\Users\Administrador.WIN-DUOGLHGMSST\AppData\Local\Programs\Python\Python37\lib\site-packages\waitress\task.py", line 434, in execute
    app_iter = self.channel.server.application(environ, start_response)
  File "C:\Users\Administrador.WIN-DUOGLHGMSST\AppData\Local\Programs\Python\Python37\lib\site-packages\flask\app.py", line 2091, in __call__
    return self.wsgi_app(environ, start_response)
  File "C:\Users\Administrador.WIN-DUOGLHGMSST\AppData\Local\Programs\Python\Python37\lib\site-packages\flask\app.py", line 2076, in wsgi_app
    response = self.handle_exception(e)
  File "C:\Users\Administrador.WIN-DUOGLHGMSST\AppData\Local\Programs\Python\Python37\lib\site-packages\flask\app.py", line 2073, in wsgi_app
    response = self.full_dispatch_request()
  File "C:\Users\Administrador.WIN-DUOGLHGMSST\AppData\Local\Programs\Python\Python37\lib\site-packages\flask\app.py", line 1518, in full_dispatch_request
    rv = self.handle_user_exception(e)
  File "C:\Users\Administrador.WIN-DUOGLHGMSST\AppData\Local\Programs\Python\Python37\lib\site-packages\flask\app.py", line 1516, in full_dispatch_request
    rv = self.dispatch_request()
  File "C:\Users\Administrador.WIN-DUOGLHGMSST\AppData\Local\Programs\Python\Python37\lib\site-packages\flask\app.py", line 1502, in dispatch_request
    return self.ensure_sync(self.view_functions[rule.endpoint])(**req.view_args)
  File "C:\xampp\htdocs\CLANAD_PY\FlaskSecurity\app\decorators.py", line 11, in secure_function
    return func(*args, **kwargs)
  File "C:\xampp\htdocs\CLANAD_PY\FlaskSecurity\app\src\Actividad.py", line 344, in agregarcie10
    if session["paCie10"] is not None:
KeyError: 'paCie10'
{'TIME':2022-02-04 08:11:10,517,'ADDRESS':'10.10.150.80','URL': 'http://10.10.110.13:8001/agregar/cie10/0','TYPE':'ERROR','MODULE':'channel','MSG':{Exception while serving /agregar/cie10/0}}
Traceback (most recent call last):
  File "C:\Users\Administrador.WIN-DUOGLHGMSST\AppData\Local\Programs\Python\Python37\lib\site-packages\waitress\channel.py", line 397, in service
    task.service()
  File "C:\Users\Administrador.WIN-DUOGLHGMSST\AppData\Local\Programs\Python\Python37\lib\site-packages\waitress\task.py", line 168, in service
    self.execute()
  File "C:\Users\Administrador.WIN-DUOGLHGMSST\AppData\Local\Programs\Python\Python37\lib\site-packages\waitress\task.py", line 434, in execute
    app_iter = self.channel.server.application(environ, start_response)
  File "C:\Users\Administrador.WIN-DUOGLHGMSST\AppData\Local\Programs\Python\Python37\lib\site-packages\flask\app.py", line 2091, in __call__
    return self.wsgi_app(environ, start_response)
  File "C:\Users\Administrador.WIN-DUOGLHGMSST\AppData\Local\Programs\Python\Python37\lib\site-packages\flask\app.py", line 2076, in wsgi_app
    response = self.handle_exception(e)
  File "C:\Users\Administrador.WIN-DUOGLHGMSST\AppData\Local\Programs\Python\Python37\lib\site-packages\flask\app.py", line 2073, in wsgi_app
    response = self.full_dispatch_request()
  File "C:\Users\Administrador.WIN-DUOGLHGMSST\AppData\Local\Programs\Python\Python37\lib\site-packages\flask\app.py", line 1518, in full_dispatch_request
    rv = self.handle_user_exception(e)
  File "C:\Users\Administrador.WIN-DUOGLHGMSST\AppData\Local\Programs\Python\Python37\lib\site-packages\flask\app.py", line 1516, in full_dispatch_request
    rv = self.dispatch_request()
  File "C:\Users\Administrador.WIN-DUOGLHGMSST\AppData\Local\Programs\Python\Python37\lib\site-packages\flask\app.py", line 1502, in dispatch_request
    return self.ensure_sync(self.view_functions[rule.endpoint])(**req.view_args)
  File "C:\xampp\htdocs\CLANAD_PY\FlaskSecurity\app\decorators.py", line 11, in secure_function
    return func(*args, **kwargs)
  File "C:\xampp\htdocs\CLANAD_PY\FlaskSecurity\app\src\Actividad.py", line 344, in agregarcie10
    if session["paCie10"] is not None:
KeyError: 'paCie10'
{'TIME':2022-02-04 10:54:50,996,'ADDRESS':'127.0.0.1','URL': 'http://localhost:8001/test','TYPE':'ERROR','MODULE':'channel','MSG':{Exception while serving /test}}
Traceback (most recent call last):
  File "C:\Users\Administrador.WIN-DUOGLHGMSST\AppData\Local\Programs\Python\Python37\lib\site-packages\waitress\channel.py", line 397, in service
    task.service()
  File "C:\Users\Administrador.WIN-DUOGLHGMSST\AppData\Local\Programs\Python\Python37\lib\site-packages\waitress\task.py", line 168, in service
    self.execute()
  File "C:\Users\Administrador.WIN-DUOGLHGMSST\AppData\Local\Programs\Python\Python37\lib\site-packages\waitress\task.py", line 434, in execute
    app_iter = self.channel.server.application(environ, start_response)
  File "C:\Users\Administrador.WIN-DUOGLHGMSST\AppData\Local\Programs\Python\Python37\lib\site-packages\flask\app.py", line 2091, in __call__
    return self.wsgi_app(environ, start_response)
  File "C:\Users\Administrador.WIN-DUOGLHGMSST\AppData\Local\Programs\Python\Python37\lib\site-packages\flask\app.py", line 2076, in wsgi_app
    response = self.handle_exception(e)
  File "C:\Users\Administrador.WIN-DUOGLHGMSST\AppData\Local\Programs\Python\Python37\lib\site-packages\flask\app.py", line 2073, in wsgi_app
    response = self.full_dispatch_request()
  File "C:\Users\Administrador.WIN-DUOGLHGMSST\AppData\Local\Programs\Python\Python37\lib\site-packages\flask\app.py", line 1518, in full_dispatch_request
    rv = self.handle_user_exception(e)
  File "C:\Users\Administrador.WIN-DUOGLHGMSST\AppData\Local\Programs\Python\Python37\lib\site-packages\flask\app.py", line 1516, in full_dispatch_request
    rv = self.dispatch_request()
  File "C:\Users\Administrador.WIN-DUOGLHGMSST\AppData\Local\Programs\Python\Python37\lib\site-packages\flask\app.py", line 1502, in dispatch_request
    return self.ensure_sync(self.view_functions[rule.endpoint])(**req.view_args)
TypeError: ver_archivo() missing 1 required positional argument: 'pcCodigo'
{'TIME':2022-02-04 10:56:34,459,'ADDRESS':'127.0.0.1','URL': 'http://localhost:8001/test','TYPE':'ERROR','MODULE':'channel','MSG':{Exception while serving /test}}
Traceback (most recent call last):
  File "C:\Users\Administrador.WIN-DUOGLHGMSST\AppData\Local\Programs\Python\Python37\lib\site-packages\waitress\channel.py", line 397, in service
    task.service()
  File "C:\Users\Administrador.WIN-DUOGLHGMSST\AppData\Local\Programs\Python\Python37\lib\site-packages\waitress\task.py", line 168, in service
    self.execute()
  File "C:\Users\Administrador.WIN-DUOGLHGMSST\AppData\Local\Programs\Python\Python37\lib\site-packages\waitress\task.py", line 434, in execute
    app_iter = self.channel.server.application(environ, start_response)
  File "C:\Users\Administrador.WIN-DUOGLHGMSST\AppData\Local\Programs\Python\Python37\lib\site-packages\flask\app.py", line 2091, in __call__
    return self.wsgi_app(environ, start_response)
  File "C:\Users\Administrador.WIN-DUOGLHGMSST\AppData\Local\Programs\Python\Python37\lib\site-packages\flask\app.py", line 2076, in wsgi_app
    response = self.handle_exception(e)
  File "C:\Users\Administrador.WIN-DUOGLHGMSST\AppData\Local\Programs\Python\Python37\lib\site-packages\flask\app.py", line 2073, in wsgi_app
    response = self.full_dispatch_request()
  File "C:\Users\Administrador.WIN-DUOGLHGMSST\AppData\Local\Programs\Python\Python37\lib\site-packages\flask\app.py", line 1518, in full_dispatch_request
    rv = self.handle_user_exception(e)
  File "C:\Users\Administrador.WIN-DUOGLHGMSST\AppData\Local\Programs\Python\Python37\lib\site-packages\flask\app.py", line 1516, in full_dispatch_request
    rv = self.dispatch_request()
  File "C:\Users\Administrador.WIN-DUOGLHGMSST\AppData\Local\Programs\Python\Python37\lib\site-packages\flask\app.py", line 1502, in dispatch_request
    return self.ensure_sync(self.view_functions[rule.endpoint])(**req.view_args)
TypeError: ver_archivo() missing 1 required positional argument: 'pcCodigo'
{'TIME':2022-02-04 10:57:20,564,'ADDRESS':'127.0.0.1','URL': 'http://localhost:8001/test','TYPE':'ERROR','MODULE':'channel','MSG':{Exception while serving /test}}
Traceback (most recent call last):
  File "C:\Users\Administrador.WIN-DUOGLHGMSST\AppData\Local\Programs\Python\Python37\lib\site-packages\waitress\channel.py", line 397, in service
    task.service()
  File "C:\Users\Administrador.WIN-DUOGLHGMSST\AppData\Local\Programs\Python\Python37\lib\site-packages\waitress\task.py", line 168, in service
    self.execute()
  File "C:\Users\Administrador.WIN-DUOGLHGMSST\AppData\Local\Programs\Python\Python37\lib\site-packages\waitress\task.py", line 434, in execute
    app_iter = self.channel.server.application(environ, start_response)
  File "C:\Users\Administrador.WIN-DUOGLHGMSST\AppData\Local\Programs\Python\Python37\lib\site-packages\flask\app.py", line 2091, in __call__
    return self.wsgi_app(environ, start_response)
  File "C:\Users\Administrador.WIN-DUOGLHGMSST\AppData\Local\Programs\Python\Python37\lib\site-packages\flask\app.py", line 2076, in wsgi_app
    response = self.handle_exception(e)
  File "C:\Users\Administrador.WIN-DUOGLHGMSST\AppData\Local\Programs\Python\Python37\lib\site-packages\flask\app.py", line 2073, in wsgi_app
    response = self.full_dispatch_request()
  File "C:\Users\Administrador.WIN-DUOGLHGMSST\AppData\Local\Programs\Python\Python37\lib\site-packages\flask\app.py", line 1518, in full_dispatch_request
    rv = self.handle_user_exception(e)
  File "C:\Users\Administrador.WIN-DUOGLHGMSST\AppData\Local\Programs\Python\Python37\lib\site-packages\flask\app.py", line 1516, in full_dispatch_request
    rv = self.dispatch_request()
  File "C:\Users\Administrador.WIN-DUOGLHGMSST\AppData\Local\Programs\Python\Python37\lib\site-packages\flask\app.py", line 1502, in dispatch_request
    return self.ensure_sync(self.view_functions[rule.endpoint])(**req.view_args)
  File "C:\xampp\htdocs\CLANAD_PY\FlaskSecurity\app\src\Actividad.py", line 390, in ver_archivo
    from app.CBase import CBase
  File "C:\xampp\htdocs\CLANAD_PY\FlaskSecurity\app\CBase.py", line 1, in <module>
    from flask import current_ap
ImportError: cannot import name 'current_ap' from 'flask' (C:\Users\Administrador.WIN-DUOGLHGMSST\AppData\Local\Programs\Python\Python37\lib\site-packages\flask\__init__.py)
{'TIME':2022-02-04 10:58:14,000,'ADDRESS':'127.0.0.1','URL': 'http://localhost:8001/test','TYPE':'ERROR','MODULE':'channel','MSG':{Exception while serving /test}}
Traceback (most recent call last):
  File "C:\Users\Administrador.WIN-DUOGLHGMSST\AppData\Local\Programs\Python\Python37\lib\site-packages\waitress\channel.py", line 397, in service
    task.service()
  File "C:\Users\Administrador.WIN-DUOGLHGMSST\AppData\Local\Programs\Python\Python37\lib\site-packages\waitress\task.py", line 168, in service
    self.execute()
  File "C:\Users\Administrador.WIN-DUOGLHGMSST\AppData\Local\Programs\Python\Python37\lib\site-packages\waitress\task.py", line 434, in execute
    app_iter = self.channel.server.application(environ, start_response)
  File "C:\Users\Administrador.WIN-DUOGLHGMSST\AppData\Local\Programs\Python\Python37\lib\site-packages\flask\app.py", line 2091, in __call__
    return self.wsgi_app(environ, start_response)
  File "C:\Users\Administrador.WIN-DUOGLHGMSST\AppData\Local\Programs\Python\Python37\lib\site-packages\flask\app.py", line 2076, in wsgi_app
    response = self.handle_exception(e)
  File "C:\Users\Administrador.WIN-DUOGLHGMSST\AppData\Local\Programs\Python\Python37\lib\site-packages\flask\app.py", line 2073, in wsgi_app
    response = self.full_dispatch_request()
  File "C:\Users\Administrador.WIN-DUOGLHGMSST\AppData\Local\Programs\Python\Python37\lib\site-packages\flask\app.py", line 1518, in full_dispatch_request
    rv = self.handle_user_exception(e)
  File "C:\Users\Administrador.WIN-DUOGLHGMSST\AppData\Local\Programs\Python\Python37\lib\site-packages\flask\app.py", line 1516, in full_dispatch_request
    rv = self.dispatch_request()
  File "C:\Users\Administrador.WIN-DUOGLHGMSST\AppData\Local\Programs\Python\Python37\lib\site-packages\flask\app.py", line 1502, in dispatch_request
    return self.ensure_sync(self.view_functions[rule.endpoint])(**req.view_args)
  File "C:\xampp\htdocs\CLANAD_PY\FlaskSecurity\app\src\Actividad.py", line 390, in ver_archivo
    from app.CBase import CBase
  File "C:\xampp\htdocs\CLANAD_PY\FlaskSecurity\app\CBase.py", line 1, in <module>
    from flask import current_ap
ImportError: cannot import name 'current_ap' from 'flask' (C:\Users\Administrador.WIN-DUOGLHGMSST\AppData\Local\Programs\Python\Python37\lib\site-packages\flask\__init__.py)
{'TIME':2022-02-04 10:59:06,814,'ADDRESS':'127.0.0.1','URL': 'http://localhost:8001/test','TYPE':'ERROR','MODULE':'channel','MSG':{Exception while serving /test}}
Traceback (most recent call last):
  File "C:\Users\Administrador.WIN-DUOGLHGMSST\AppData\Local\Programs\Python\Python37\lib\site-packages\waitress\channel.py", line 397, in service
    task.service()
  File "C:\Users\Administrador.WIN-DUOGLHGMSST\AppData\Local\Programs\Python\Python37\lib\site-packages\waitress\task.py", line 168, in service
    self.execute()
  File "C:\Users\Administrador.WIN-DUOGLHGMSST\AppData\Local\Programs\Python\Python37\lib\site-packages\waitress\task.py", line 434, in execute
    app_iter = self.channel.server.application(environ, start_response)
  File "C:\Users\Administrador.WIN-DUOGLHGMSST\AppData\Local\Programs\Python\Python37\lib\site-packages\flask\app.py", line 2091, in __call__
    return self.wsgi_app(environ, start_response)
  File "C:\Users\Administrador.WIN-DUOGLHGMSST\AppData\Local\Programs\Python\Python37\lib\site-packages\flask\app.py", line 2076, in wsgi_app
    response = self.handle_exception(e)
  File "C:\Users\Administrador.WIN-DUOGLHGMSST\AppData\Local\Programs\Python\Python37\lib\site-packages\flask\app.py", line 2073, in wsgi_app
    response = self.full_dispatch_request()
  File "C:\Users\Administrador.WIN-DUOGLHGMSST\AppData\Local\Programs\Python\Python37\lib\site-packages\flask\app.py", line 1518, in full_dispatch_request
    rv = self.handle_user_exception(e)
  File "C:\Users\Administrador.WIN-DUOGLHGMSST\AppData\Local\Programs\Python\Python37\lib\site-packages\flask\app.py", line 1516, in full_dispatch_request
    rv = self.dispatch_request()
  File "C:\Users\Administrador.WIN-DUOGLHGMSST\AppData\Local\Programs\Python\Python37\lib\site-packages\flask\app.py", line 1502, in dispatch_request
    return self.ensure_sync(self.view_functions[rule.endpoint])(**req.view_args)
  File "C:\xampp\htdocs\CLANAD_PY\FlaskSecurity\app\src\Actividad.py", line 390, in ver_archivo
    from app.CBase import CBase
  File "C:\xampp\htdocs\CLANAD_PY\FlaskSecurity\app\CBase.py", line 3, in <module>
    class CBase:
  File "C:\xampp\htdocs\CLANAD_PY\FlaskSecurity\app\CBase.py", line 8, in CBase
    def encrypt(txt:str)->None|str:
TypeError: unsupported operand type(s) for |: 'NoneType' and 'type'
{'TIME':2022-02-04 11:02:22,157,'ADDRESS':'127.0.0.1','URL': 'http://localhost:8001/test','TYPE':'ERROR','MODULE':'channel','MSG':{Exception while serving /test}}
Traceback (most recent call last):
  File "C:\Users\Administrador.WIN-DUOGLHGMSST\AppData\Local\Programs\Python\Python37\lib\site-packages\waitress\channel.py", line 397, in service
    task.service()
  File "C:\Users\Administrador.WIN-DUOGLHGMSST\AppData\Local\Programs\Python\Python37\lib\site-packages\waitress\task.py", line 168, in service
    self.execute()
  File "C:\Users\Administrador.WIN-DUOGLHGMSST\AppData\Local\Programs\Python\Python37\lib\site-packages\waitress\task.py", line 434, in execute
    app_iter = self.channel.server.application(environ, start_response)
  File "C:\Users\Administrador.WIN-DUOGLHGMSST\AppData\Local\Programs\Python\Python37\lib\site-packages\flask\app.py", line 2091, in __call__
    return self.wsgi_app(environ, start_response)
  File "C:\Users\Administrador.WIN-DUOGLHGMSST\AppData\Local\Programs\Python\Python37\lib\site-packages\flask\app.py", line 2076, in wsgi_app
    response = self.handle_exception(e)
  File "C:\Users\Administrador.WIN-DUOGLHGMSST\AppData\Local\Programs\Python\Python37\lib\site-packages\flask\app.py", line 2073, in wsgi_app
    response = self.full_dispatch_request()
  File "C:\Users\Administrador.WIN-DUOGLHGMSST\AppData\Local\Programs\Python\Python37\lib\site-packages\flask\app.py", line 1518, in full_dispatch_request
    rv = self.handle_user_exception(e)
  File "C:\Users\Administrador.WIN-DUOGLHGMSST\AppData\Local\Programs\Python\Python37\lib\site-packages\flask\app.py", line 1516, in full_dispatch_request
    rv = self.dispatch_request()
  File "C:\Users\Administrador.WIN-DUOGLHGMSST\AppData\Local\Programs\Python\Python37\lib\site-packages\flask\app.py", line 1502, in dispatch_request
    return self.ensure_sync(self.view_functions[rule.endpoint])(**req.view_args)
  File "C:\xampp\htdocs\CLANAD_PY\FlaskSecurity\app\src\Actividad.py", line 390, in ver_archivo
    from app.CBase import CBase
  File "C:\xampp\htdocs\CLANAD_PY\FlaskSecurity\app\CBase.py", line 3, in <module>
    class CBase:
  File "C:\xampp\htdocs\CLANAD_PY\FlaskSecurity\app\CBase.py", line 8, in CBase
    def encrypt(txt:str)->None|str:
TypeError: unsupported operand type(s) for |: 'NoneType' and 'type'
{'TIME':2022-02-04 11:05:23,817,'ADDRESS':'127.0.0.1','URL': 'http://localhost:8001/test','TYPE':'ERROR','MODULE':'channel','MSG':{Exception while serving /test}}
Traceback (most recent call last):
  File "C:\Users\Administrador.WIN-DUOGLHGMSST\AppData\Local\Programs\Python\Python37\lib\site-packages\waitress\channel.py", line 397, in service
    task.service()
  File "C:\Users\Administrador.WIN-DUOGLHGMSST\AppData\Local\Programs\Python\Python37\lib\site-packages\waitress\task.py", line 168, in service
    self.execute()
  File "C:\Users\Administrador.WIN-DUOGLHGMSST\AppData\Local\Programs\Python\Python37\lib\site-packages\waitress\task.py", line 434, in execute
    app_iter = self.channel.server.application(environ, start_response)
  File "C:\Users\Administrador.WIN-DUOGLHGMSST\AppData\Local\Programs\Python\Python37\lib\site-packages\flask\app.py", line 2091, in __call__
    return self.wsgi_app(environ, start_response)
  File "C:\Users\Administrador.WIN-DUOGLHGMSST\AppData\Local\Programs\Python\Python37\lib\site-packages\flask\app.py", line 2076, in wsgi_app
    response = self.handle_exception(e)
  File "C:\Users\Administrador.WIN-DUOGLHGMSST\AppData\Local\Programs\Python\Python37\lib\site-packages\flask\app.py", line 2073, in wsgi_app
    response = self.full_dispatch_request()
  File "C:\Users\Administrador.WIN-DUOGLHGMSST\AppData\Local\Programs\Python\Python37\lib\site-packages\flask\app.py", line 1518, in full_dispatch_request
    rv = self.handle_user_exception(e)
  File "C:\Users\Administrador.WIN-DUOGLHGMSST\AppData\Local\Programs\Python\Python37\lib\site-packages\flask\app.py", line 1516, in full_dispatch_request
    rv = self.dispatch_request()
  File "C:\Users\Administrador.WIN-DUOGLHGMSST\AppData\Local\Programs\Python\Python37\lib\site-packages\flask\app.py", line 1502, in dispatch_request
    return self.ensure_sync(self.view_functions[rule.endpoint])(**req.view_args)
  File "C:\xampp\htdocs\CLANAD_PY\FlaskSecurity\app\src\Actividad.py", line 390, in codigo_hash
    from app.CBase import CBase
  File "C:\xampp\htdocs\CLANAD_PY\FlaskSecurity\app\CBase.py", line 3, in <module>
    class CBase:
  File "C:\xampp\htdocs\CLANAD_PY\FlaskSecurity\app\CBase.py", line 8, in CBase
    def encrypt(txt:str)->None|str:
TypeError: unsupported operand type(s) for |: 'NoneType' and 'type'
{'TIME':2022-02-04 11:06:09,432,'ADDRESS':'127.0.0.1','URL': 'http://localhost:8001/test','TYPE':'ERROR','MODULE':'channel','MSG':{Exception while serving /test}}
Traceback (most recent call last):
  File "C:\Users\Administrador.WIN-DUOGLHGMSST\AppData\Local\Programs\Python\Python37\lib\site-packages\waitress\channel.py", line 397, in service
    task.service()
  File "C:\Users\Administrador.WIN-DUOGLHGMSST\AppData\Local\Programs\Python\Python37\lib\site-packages\waitress\task.py", line 168, in service
    self.execute()
  File "C:\Users\Administrador.WIN-DUOGLHGMSST\AppData\Local\Programs\Python\Python37\lib\site-packages\waitress\task.py", line 434, in execute
    app_iter = self.channel.server.application(environ, start_response)
  File "C:\Users\Administrador.WIN-DUOGLHGMSST\AppData\Local\Programs\Python\Python37\lib\site-packages\flask\app.py", line 2091, in __call__
    return self.wsgi_app(environ, start_response)
  File "C:\Users\Administrador.WIN-DUOGLHGMSST\AppData\Local\Programs\Python\Python37\lib\site-packages\flask\app.py", line 2076, in wsgi_app
    response = self.handle_exception(e)
  File "C:\Users\Administrador.WIN-DUOGLHGMSST\AppData\Local\Programs\Python\Python37\lib\site-packages\flask\app.py", line 2073, in wsgi_app
    response = self.full_dispatch_request()
  File "C:\Users\Administrador.WIN-DUOGLHGMSST\AppData\Local\Programs\Python\Python37\lib\site-packages\flask\app.py", line 1518, in full_dispatch_request
    rv = self.handle_user_exception(e)
  File "C:\Users\Administrador.WIN-DUOGLHGMSST\AppData\Local\Programs\Python\Python37\lib\site-packages\flask\app.py", line 1516, in full_dispatch_request
    rv = self.dispatch_request()
  File "C:\Users\Administrador.WIN-DUOGLHGMSST\AppData\Local\Programs\Python\Python37\lib\site-packages\flask\app.py", line 1502, in dispatch_request
    return self.ensure_sync(self.view_functions[rule.endpoint])(**req.view_args)
  File "C:\xampp\htdocs\CLANAD_PY\FlaskSecurity\app\src\Actividad.py", line 392, in codigo_hash
    from app.CBase import CBase
  File "C:\xampp\htdocs\CLANAD_PY\FlaskSecurity\app\CBase.py", line 3, in <module>
    class CBase:
  File "C:\xampp\htdocs\CLANAD_PY\FlaskSecurity\app\CBase.py", line 8, in CBase
    def encrypt(txt:str)->None|str:
TypeError: unsupported operand type(s) for |: 'NoneType' and 'type'
{'TIME':2022-02-04 11:06:45,015,'ADDRESS':'127.0.0.1','URL': 'http://localhost:8001/test','TYPE':'ERROR','MODULE':'channel','MSG':{Exception while serving /test}}
Traceback (most recent call last):
  File "C:\Users\Administrador.WIN-DUOGLHGMSST\AppData\Local\Programs\Python\Python37\lib\site-packages\waitress\channel.py", line 397, in service
    task.service()
  File "C:\Users\Administrador.WIN-DUOGLHGMSST\AppData\Local\Programs\Python\Python37\lib\site-packages\waitress\task.py", line 168, in service
    self.execute()
  File "C:\Users\Administrador.WIN-DUOGLHGMSST\AppData\Local\Programs\Python\Python37\lib\site-packages\waitress\task.py", line 434, in execute
    app_iter = self.channel.server.application(environ, start_response)
  File "C:\Users\Administrador.WIN-DUOGLHGMSST\AppData\Local\Programs\Python\Python37\lib\site-packages\flask\app.py", line 2091, in __call__
    return self.wsgi_app(environ, start_response)
  File "C:\Users\Administrador.WIN-DUOGLHGMSST\AppData\Local\Programs\Python\Python37\lib\site-packages\flask\app.py", line 2076, in wsgi_app
    response = self.handle_exception(e)
  File "C:\Users\Administrador.WIN-DUOGLHGMSST\AppData\Local\Programs\Python\Python37\lib\site-packages\flask\app.py", line 2073, in wsgi_app
    response = self.full_dispatch_request()
  File "C:\Users\Administrador.WIN-DUOGLHGMSST\AppData\Local\Programs\Python\Python37\lib\site-packages\flask\app.py", line 1518, in full_dispatch_request
    rv = self.handle_user_exception(e)
  File "C:\Users\Administrador.WIN-DUOGLHGMSST\AppData\Local\Programs\Python\Python37\lib\site-packages\flask\app.py", line 1516, in full_dispatch_request
    rv = self.dispatch_request()
  File "C:\Users\Administrador.WIN-DUOGLHGMSST\AppData\Local\Programs\Python\Python37\lib\site-packages\flask\app.py", line 1502, in dispatch_request
    return self.ensure_sync(self.view_functions[rule.endpoint])(**req.view_args)
  File "C:\xampp\htdocs\CLANAD_PY\FlaskSecurity\app\src\Actividad.py", line 391, in codigo_hash
    from ..CBase import CBase
  File "C:\xampp\htdocs\CLANAD_PY\FlaskSecurity\app\CBase.py", line 3, in <module>
    class CBase:
  File "C:\xampp\htdocs\CLANAD_PY\FlaskSecurity\app\CBase.py", line 8, in CBase
    def encrypt(txt:str)->None|str:
TypeError: unsupported operand type(s) for |: 'NoneType' and 'type'
{'TIME':2022-02-04 11:07:04,758,'ADDRESS':'127.0.0.1','URL': 'http://localhost:8001/test','TYPE':'ERROR','MODULE':'channel','MSG':{Exception while serving /test}}
Traceback (most recent call last):
  File "C:\Users\Administrador.WIN-DUOGLHGMSST\AppData\Local\Programs\Python\Python37\lib\site-packages\waitress\channel.py", line 397, in service
    task.service()
  File "C:\Users\Administrador.WIN-DUOGLHGMSST\AppData\Local\Programs\Python\Python37\lib\site-packages\waitress\task.py", line 168, in service
    self.execute()
  File "C:\Users\Administrador.WIN-DUOGLHGMSST\AppData\Local\Programs\Python\Python37\lib\site-packages\waitress\task.py", line 434, in execute
    app_iter = self.channel.server.application(environ, start_response)
  File "C:\Users\Administrador.WIN-DUOGLHGMSST\AppData\Local\Programs\Python\Python37\lib\site-packages\flask\app.py", line 2091, in __call__
    return self.wsgi_app(environ, start_response)
  File "C:\Users\Administrador.WIN-DUOGLHGMSST\AppData\Local\Programs\Python\Python37\lib\site-packages\flask\app.py", line 2076, in wsgi_app
    response = self.handle_exception(e)
  File "C:\Users\Administrador.WIN-DUOGLHGMSST\AppData\Local\Programs\Python\Python37\lib\site-packages\flask\app.py", line 2073, in wsgi_app
    response = self.full_dispatch_request()
  File "C:\Users\Administrador.WIN-DUOGLHGMSST\AppData\Local\Programs\Python\Python37\lib\site-packages\flask\app.py", line 1518, in full_dispatch_request
    rv = self.handle_user_exception(e)
  File "C:\Users\Administrador.WIN-DUOGLHGMSST\AppData\Local\Programs\Python\Python37\lib\site-packages\flask\app.py", line 1516, in full_dispatch_request
    rv = self.dispatch_request()
  File "C:\Users\Administrador.WIN-DUOGLHGMSST\AppData\Local\Programs\Python\Python37\lib\site-packages\flask\app.py", line 1502, in dispatch_request
    return self.ensure_sync(self.view_functions[rule.endpoint])(**req.view_args)
  File "C:\xampp\htdocs\CLANAD_PY\FlaskSecurity\app\src\Actividad.py", line 391, in codigo_hash
    from .CBase import CBase
ModuleNotFoundError: No module named 'app.src.CBase'
{'TIME':2022-02-04 11:08:00,673,'ADDRESS':'127.0.0.1','URL': 'http://localhost:8001/test','TYPE':'ERROR','MODULE':'channel','MSG':{Exception while serving /test}}
Traceback (most recent call last):
  File "C:\Users\Administrador.WIN-DUOGLHGMSST\AppData\Local\Programs\Python\Python37\lib\site-packages\waitress\channel.py", line 397, in service
    task.service()
  File "C:\Users\Administrador.WIN-DUOGLHGMSST\AppData\Local\Programs\Python\Python37\lib\site-packages\waitress\task.py", line 168, in service
    self.execute()
  File "C:\Users\Administrador.WIN-DUOGLHGMSST\AppData\Local\Programs\Python\Python37\lib\site-packages\waitress\task.py", line 434, in execute
    app_iter = self.channel.server.application(environ, start_response)
  File "C:\Users\Administrador.WIN-DUOGLHGMSST\AppData\Local\Programs\Python\Python37\lib\site-packages\flask\app.py", line 2091, in __call__
    return self.wsgi_app(environ, start_response)
  File "C:\Users\Administrador.WIN-DUOGLHGMSST\AppData\Local\Programs\Python\Python37\lib\site-packages\flask\app.py", line 2076, in wsgi_app
    response = self.handle_exception(e)
  File "C:\Users\Administrador.WIN-DUOGLHGMSST\AppData\Local\Programs\Python\Python37\lib\site-packages\flask\app.py", line 2073, in wsgi_app
    response = self.full_dispatch_request()
  File "C:\Users\Administrador.WIN-DUOGLHGMSST\AppData\Local\Programs\Python\Python37\lib\site-packages\flask\app.py", line 1518, in full_dispatch_request
    rv = self.handle_user_exception(e)
  File "C:\Users\Administrador.WIN-DUOGLHGMSST\AppData\Local\Programs\Python\Python37\lib\site-packages\flask\app.py", line 1516, in full_dispatch_request
    rv = self.dispatch_request()
  File "C:\Users\Administrador.WIN-DUOGLHGMSST\AppData\Local\Programs\Python\Python37\lib\site-packages\flask\app.py", line 1502, in dispatch_request
    return self.ensure_sync(self.view_functions[rule.endpoint])(**req.view_args)
  File "C:\xampp\htdocs\CLANAD_PY\FlaskSecurity\app\src\Actividad.py", line 391, in codigo_hash
    import app.CBase
  File "C:\xampp\htdocs\CLANAD_PY\FlaskSecurity\app\CBase.py", line 3, in <module>
    class CBase:
  File "C:\xampp\htdocs\CLANAD_PY\FlaskSecurity\app\CBase.py", line 8, in CBase
    def encrypt(txt:str)->None|str:
TypeError: unsupported operand type(s) for |: 'NoneType' and 'type'
{'TIME':2022-02-04 11:32:07,520,'ADDRESS':'127.0.0.1','URL': 'http://localhost:8001/test','TYPE':'ERROR','MODULE':'channel','MSG':{Exception while serving /test}}
Traceback (most recent call last):
  File "C:\Users\Administrador.WIN-DUOGLHGMSST\AppData\Local\Programs\Python\Python37\lib\site-packages\waitress\channel.py", line 397, in service
    task.service()
  File "C:\Users\Administrador.WIN-DUOGLHGMSST\AppData\Local\Programs\Python\Python37\lib\site-packages\waitress\task.py", line 168, in service
    self.execute()
  File "C:\Users\Administrador.WIN-DUOGLHGMSST\AppData\Local\Programs\Python\Python37\lib\site-packages\waitress\task.py", line 434, in execute
    app_iter = self.channel.server.application(environ, start_response)
  File "C:\Users\Administrador.WIN-DUOGLHGMSST\AppData\Local\Programs\Python\Python37\lib\site-packages\flask\app.py", line 2091, in __call__
    return self.wsgi_app(environ, start_response)
  File "C:\Users\Administrador.WIN-DUOGLHGMSST\AppData\Local\Programs\Python\Python37\lib\site-packages\flask\app.py", line 2076, in wsgi_app
    response = self.handle_exception(e)
  File "C:\Users\Administrador.WIN-DUOGLHGMSST\AppData\Local\Programs\Python\Python37\lib\site-packages\flask\app.py", line 2073, in wsgi_app
    response = self.full_dispatch_request()
  File "C:\Users\Administrador.WIN-DUOGLHGMSST\AppData\Local\Programs\Python\Python37\lib\site-packages\flask\app.py", line 1519, in full_dispatch_request
    return self.finalize_request(rv)
  File "C:\Users\Administrador.WIN-DUOGLHGMSST\AppData\Local\Programs\Python\Python37\lib\site-packages\flask\app.py", line 1538, in finalize_request
    response = self.make_response(rv)
  File "C:\Users\Administrador.WIN-DUOGLHGMSST\AppData\Local\Programs\Python\Python37\lib\site-packages\flask\app.py", line 1716, in make_response
    rv = jsonify(rv)
  File "C:\Users\Administrador.WIN-DUOGLHGMSST\AppData\Local\Programs\Python\Python37\lib\site-packages\flask\json\__init__.py", line 355, in jsonify
    f"{dumps(data, indent=indent, separators=separators)}\n",
  File "C:\Users\Administrador.WIN-DUOGLHGMSST\AppData\Local\Programs\Python\Python37\lib\site-packages\flask\json\__init__.py", line 133, in dumps
    rv = _json.dumps(obj, **kwargs)
  File "C:\Users\Administrador.WIN-DUOGLHGMSST\AppData\Local\Programs\Python\Python37\lib\json\__init__.py", line 238, in dumps
    **kw).encode(obj)
  File "C:\Users\Administrador.WIN-DUOGLHGMSST\AppData\Local\Programs\Python\Python37\lib\json\encoder.py", line 201, in encode
    chunks = list(chunks)
  File "C:\Users\Administrador.WIN-DUOGLHGMSST\AppData\Local\Programs\Python\Python37\lib\json\encoder.py", line 431, in _iterencode
    yield from _iterencode_dict(o, _current_indent_level)
  File "C:\Users\Administrador.WIN-DUOGLHGMSST\AppData\Local\Programs\Python\Python37\lib\json\encoder.py", line 405, in _iterencode_dict
    yield from chunks
  File "C:\Users\Administrador.WIN-DUOGLHGMSST\AppData\Local\Programs\Python\Python37\lib\json\encoder.py", line 438, in _iterencode
    o = _default(o)
  File "C:\Users\Administrador.WIN-DUOGLHGMSST\AppData\Local\Programs\Python\Python37\lib\site-packages\flask\json\__init__.py", line 57, in default
    return super().default(o)
  File "C:\Users\Administrador.WIN-DUOGLHGMSST\AppData\Local\Programs\Python\Python37\lib\json\encoder.py", line 179, in default
    raise TypeError(f'Object of type {o.__class__.__name__} '
TypeError: Object of type bytes is not JSON serializable
{'TIME':2022-02-04 11:33:20,445,'ADDRESS':'127.0.0.1','URL': 'http://localhost:8001/test','TYPE':'ERROR','MODULE':'channel','MSG':{Exception while serving /test}}
Traceback (most recent call last):
  File "C:\Users\Administrador.WIN-DUOGLHGMSST\AppData\Local\Programs\Python\Python37\lib\site-packages\waitress\channel.py", line 397, in service
    task.service()
  File "C:\Users\Administrador.WIN-DUOGLHGMSST\AppData\Local\Programs\Python\Python37\lib\site-packages\waitress\task.py", line 168, in service
    self.execute()
  File "C:\Users\Administrador.WIN-DUOGLHGMSST\AppData\Local\Programs\Python\Python37\lib\site-packages\waitress\task.py", line 434, in execute
    app_iter = self.channel.server.application(environ, start_response)
  File "C:\Users\Administrador.WIN-DUOGLHGMSST\AppData\Local\Programs\Python\Python37\lib\site-packages\flask\app.py", line 2091, in __call__
    return self.wsgi_app(environ, start_response)
  File "C:\Users\Administrador.WIN-DUOGLHGMSST\AppData\Local\Programs\Python\Python37\lib\site-packages\flask\app.py", line 2076, in wsgi_app
    response = self.handle_exception(e)
  File "C:\Users\Administrador.WIN-DUOGLHGMSST\AppData\Local\Programs\Python\Python37\lib\site-packages\flask\app.py", line 2073, in wsgi_app
    response = self.full_dispatch_request()
  File "C:\Users\Administrador.WIN-DUOGLHGMSST\AppData\Local\Programs\Python\Python37\lib\site-packages\flask\app.py", line 1519, in full_dispatch_request
    return self.finalize_request(rv)
  File "C:\Users\Administrador.WIN-DUOGLHGMSST\AppData\Local\Programs\Python\Python37\lib\site-packages\flask\app.py", line 1538, in finalize_request
    response = self.make_response(rv)
  File "C:\Users\Administrador.WIN-DUOGLHGMSST\AppData\Local\Programs\Python\Python37\lib\site-packages\flask\app.py", line 1716, in make_response
    rv = jsonify(rv)
  File "C:\Users\Administrador.WIN-DUOGLHGMSST\AppData\Local\Programs\Python\Python37\lib\site-packages\flask\json\__init__.py", line 355, in jsonify
    f"{dumps(data, indent=indent, separators=separators)}\n",
  File "C:\Users\Administrador.WIN-DUOGLHGMSST\AppData\Local\Programs\Python\Python37\lib\site-packages\flask\json\__init__.py", line 133, in dumps
    rv = _json.dumps(obj, **kwargs)
  File "C:\Users\Administrador.WIN-DUOGLHGMSST\AppData\Local\Programs\Python\Python37\lib\json\__init__.py", line 238, in dumps
    **kw).encode(obj)
  File "C:\Users\Administrador.WIN-DUOGLHGMSST\AppData\Local\Programs\Python\Python37\lib\json\encoder.py", line 201, in encode
    chunks = list(chunks)
  File "C:\Users\Administrador.WIN-DUOGLHGMSST\AppData\Local\Programs\Python\Python37\lib\json\encoder.py", line 431, in _iterencode
    yield from _iterencode_dict(o, _current_indent_level)
  File "C:\Users\Administrador.WIN-DUOGLHGMSST\AppData\Local\Programs\Python\Python37\lib\json\encoder.py", line 405, in _iterencode_dict
    yield from chunks
  File "C:\Users\Administrador.WIN-DUOGLHGMSST\AppData\Local\Programs\Python\Python37\lib\json\encoder.py", line 438, in _iterencode
    o = _default(o)
  File "C:\Users\Administrador.WIN-DUOGLHGMSST\AppData\Local\Programs\Python\Python37\lib\site-packages\flask\json\__init__.py", line 57, in default
    return super().default(o)
  File "C:\Users\Administrador.WIN-DUOGLHGMSST\AppData\Local\Programs\Python\Python37\lib\json\encoder.py", line 179, in default
    raise TypeError(f'Object of type {o.__class__.__name__} '
TypeError: Object of type bytes is not JSON serializable
{'TIME':2022-02-04 11:34:37,504,'ADDRESS':'127.0.0.1','URL': 'http://localhost:8001/test','TYPE':'ERROR','MODULE':'channel','MSG':{Exception while serving /test}}
Traceback (most recent call last):
  File "C:\xampp\htdocs\CLANAD_PY\FlaskSecurity\app\src\Actividad.py", line 396, in codigo_hash
    return jsonify({"OK":1, "DATA":lccodigo}),200
  File "C:\Users\Administrador.WIN-DUOGLHGMSST\AppData\Local\Programs\Python\Python37\lib\site-packages\flask\json\__init__.py", line 355, in jsonify
    f"{dumps(data, indent=indent, separators=separators)}\n",
  File "C:\Users\Administrador.WIN-DUOGLHGMSST\AppData\Local\Programs\Python\Python37\lib\site-packages\flask\json\__init__.py", line 133, in dumps
    rv = _json.dumps(obj, **kwargs)
  File "C:\Users\Administrador.WIN-DUOGLHGMSST\AppData\Local\Programs\Python\Python37\lib\json\__init__.py", line 238, in dumps
    **kw).encode(obj)
  File "C:\Users\Administrador.WIN-DUOGLHGMSST\AppData\Local\Programs\Python\Python37\lib\json\encoder.py", line 201, in encode
    chunks = list(chunks)
  File "C:\Users\Administrador.WIN-DUOGLHGMSST\AppData\Local\Programs\Python\Python37\lib\json\encoder.py", line 431, in _iterencode
    yield from _iterencode_dict(o, _current_indent_level)
  File "C:\Users\Administrador.WIN-DUOGLHGMSST\AppData\Local\Programs\Python\Python37\lib\json\encoder.py", line 405, in _iterencode_dict
    yield from chunks
  File "C:\Users\Administrador.WIN-DUOGLHGMSST\AppData\Local\Programs\Python\Python37\lib\json\encoder.py", line 438, in _iterencode
    o = _default(o)
  File "C:\Users\Administrador.WIN-DUOGLHGMSST\AppData\Local\Programs\Python\Python37\lib\site-packages\flask\json\__init__.py", line 57, in default
    return super().default(o)
  File "C:\Users\Administrador.WIN-DUOGLHGMSST\AppData\Local\Programs\Python\Python37\lib\json\encoder.py", line 179, in default
    raise TypeError(f'Object of type {o.__class__.__name__} '
TypeError: Object of type bytes is not JSON serializable

During handling of the above exception, another exception occurred:

Traceback (most recent call last):
  File "C:\Users\Administrador.WIN-DUOGLHGMSST\AppData\Local\Programs\Python\Python37\lib\site-packages\waitress\channel.py", line 397, in service
    task.service()
  File "C:\Users\Administrador.WIN-DUOGLHGMSST\AppData\Local\Programs\Python\Python37\lib\site-packages\waitress\task.py", line 168, in service
    self.execute()
  File "C:\Users\Administrador.WIN-DUOGLHGMSST\AppData\Local\Programs\Python\Python37\lib\site-packages\waitress\task.py", line 434, in execute
    app_iter = self.channel.server.application(environ, start_response)
  File "C:\Users\Administrador.WIN-DUOGLHGMSST\AppData\Local\Programs\Python\Python37\lib\site-packages\flask\app.py", line 2091, in __call__
    return self.wsgi_app(environ, start_response)
  File "C:\Users\Administrador.WIN-DUOGLHGMSST\AppData\Local\Programs\Python\Python37\lib\site-packages\flask\app.py", line 2076, in wsgi_app
    response = self.handle_exception(e)
  File "C:\Users\Administrador.WIN-DUOGLHGMSST\AppData\Local\Programs\Python\Python37\lib\site-packages\flask\app.py", line 2073, in wsgi_app
    response = self.full_dispatch_request()
  File "C:\Users\Administrador.WIN-DUOGLHGMSST\AppData\Local\Programs\Python\Python37\lib\site-packages\flask\app.py", line 1518, in full_dispatch_request
    rv = self.handle_user_exception(e)
  File "C:\Users\Administrador.WIN-DUOGLHGMSST\AppData\Local\Programs\Python\Python37\lib\site-packages\flask\app.py", line 1516, in full_dispatch_request
    rv = self.dispatch_request()
  File "C:\Users\Administrador.WIN-DUOGLHGMSST\AppData\Local\Programs\Python\Python37\lib\site-packages\flask\app.py", line 1502, in dispatch_request
    return self.ensure_sync(self.view_functions[rule.endpoint])(**req.view_args)
  File "C:\xampp\htdocs\CLANAD_PY\FlaskSecurity\app\src\Actividad.py", line 398, in codigo_hash
    print(e.__class__.__name__)
NameError: name 'e' is not defined
{'TIME':2022-02-04 11:45:51,451,'ADDRESS':'127.0.0.1','URL': 'http://localhost:8001/test','TYPE':'ERROR','MODULE':'channel','MSG':{Exception while serving /test}}
Traceback (most recent call last):
  File "C:\xampp\htdocs\CLANAD_PY\FlaskSecurity\app\src\Actividad.py", line 398, in codigo_hash
    return jsonify({"OK":1, "DATA":lccodigo}),200
  File "C:\Users\Administrador.WIN-DUOGLHGMSST\AppData\Local\Programs\Python\Python37\lib\site-packages\flask\json\__init__.py", line 355, in jsonify
    f"{dumps(data, indent=indent, separators=separators)}\n",
  File "C:\Users\Administrador.WIN-DUOGLHGMSST\AppData\Local\Programs\Python\Python37\lib\site-packages\flask\json\__init__.py", line 133, in dumps
    rv = _json.dumps(obj, **kwargs)
  File "C:\Users\Administrador.WIN-DUOGLHGMSST\AppData\Local\Programs\Python\Python37\lib\json\__init__.py", line 238, in dumps
    **kw).encode(obj)
  File "C:\Users\Administrador.WIN-DUOGLHGMSST\AppData\Local\Programs\Python\Python37\lib\json\encoder.py", line 201, in encode
    chunks = list(chunks)
  File "C:\Users\Administrador.WIN-DUOGLHGMSST\AppData\Local\Programs\Python\Python37\lib\json\encoder.py", line 431, in _iterencode
    yield from _iterencode_dict(o, _current_indent_level)
  File "C:\Users\Administrador.WIN-DUOGLHGMSST\AppData\Local\Programs\Python\Python37\lib\json\encoder.py", line 405, in _iterencode_dict
    yield from chunks
  File "C:\Users\Administrador.WIN-DUOGLHGMSST\AppData\Local\Programs\Python\Python37\lib\json\encoder.py", line 438, in _iterencode
    o = _default(o)
  File "C:\Users\Administrador.WIN-DUOGLHGMSST\AppData\Local\Programs\Python\Python37\lib\site-packages\flask\json\__init__.py", line 57, in default
    return super().default(o)
  File "C:\Users\Administrador.WIN-DUOGLHGMSST\AppData\Local\Programs\Python\Python37\lib\json\encoder.py", line 179, in default
    raise TypeError(f'Object of type {o.__class__.__name__} '
TypeError: Object of type bytes is not JSON serializable

During handling of the above exception, another exception occurred:

Traceback (most recent call last):
  File "C:\Users\Administrador.WIN-DUOGLHGMSST\AppData\Local\Programs\Python\Python37\lib\site-packages\waitress\channel.py", line 397, in service
    task.service()
  File "C:\Users\Administrador.WIN-DUOGLHGMSST\AppData\Local\Programs\Python\Python37\lib\site-packages\waitress\task.py", line 168, in service
    self.execute()
  File "C:\Users\Administrador.WIN-DUOGLHGMSST\AppData\Local\Programs\Python\Python37\lib\site-packages\waitress\task.py", line 434, in execute
    app_iter = self.channel.server.application(environ, start_response)
  File "C:\Users\Administrador.WIN-DUOGLHGMSST\AppData\Local\Programs\Python\Python37\lib\site-packages\flask\app.py", line 2091, in __call__
    return self.wsgi_app(environ, start_response)
  File "C:\Users\Administrador.WIN-DUOGLHGMSST\AppData\Local\Programs\Python\Python37\lib\site-packages\flask\app.py", line 2076, in wsgi_app
    response = self.handle_exception(e)
  File "C:\Users\Administrador.WIN-DUOGLHGMSST\AppData\Local\Programs\Python\Python37\lib\site-packages\flask\app.py", line 2073, in wsgi_app
    response = self.full_dispatch_request()
  File "C:\Users\Administrador.WIN-DUOGLHGMSST\AppData\Local\Programs\Python\Python37\lib\site-packages\flask\app.py", line 1518, in full_dispatch_request
    rv = self.handle_user_exception(e)
  File "C:\Users\Administrador.WIN-DUOGLHGMSST\AppData\Local\Programs\Python\Python37\lib\site-packages\flask\app.py", line 1516, in full_dispatch_request
    rv = self.dispatch_request()
  File "C:\Users\Administrador.WIN-DUOGLHGMSST\AppData\Local\Programs\Python\Python37\lib\site-packages\flask\app.py", line 1502, in dispatch_request
    return self.ensure_sync(self.view_functions[rule.endpoint])(**req.view_args)
  File "C:\xampp\htdocs\CLANAD_PY\FlaskSecurity\app\src\Actividad.py", line 401, in codigo_hash
    print(e.__class__.__name__)
NameError: name 'e' is not defined
{'TIME':2022-02-04 11:47:16,164,'ADDRESS':'127.0.0.1','URL': 'http://localhost:8001/verArchivo/Z%7Dl���%7D%2B��v�ʲ�w�8f��%02��i��D���%18%21�w�l�%11E%05�%0C�440�%0E%7F�%0C�%3C�N%04�j�UD�ܣ���42��D%1Ey','TYPE':'ERROR','MODULE':'channel','MSG':{Exception while serving /verArchivo/Z}lï¿½ï¿½ï¿½}+ï¿½ï¿½vï¿½Ê²ï¿½wï¿½8fï¿½ï¿½ï¿½ï¿½iï¿½ï¿½Dï¿½ï¿½ï¿½!ï¿½wï¿½lï¿½Eï¿½ï¿½440ï¿½ï¿½ï¿½<ï¿½Nï¿½jï¿½UDï¿½Ü£ï¿½ï¿½ï¿½42ï¿½ï¿½Dy}}
Traceback (most recent call last):
  File "C:\xampp\htdocs\CLANAD_PY\FlaskSecurity\app\src\Actividad.py", line 410, in ver_archivo_por_codigo
    if not Path(location).is_file():
NameError: name 'Path' is not defined

During handling of the above exception, another exception occurred:

Traceback (most recent call last):
  File "C:\Users\Administrador.WIN-DUOGLHGMSST\AppData\Local\Programs\Python\Python37\lib\site-packages\waitress\channel.py", line 397, in service
    task.service()
  File "C:\Users\Administrador.WIN-DUOGLHGMSST\AppData\Local\Programs\Python\Python37\lib\site-packages\waitress\task.py", line 168, in service
    self.execute()
  File "C:\Users\Administrador.WIN-DUOGLHGMSST\AppData\Local\Programs\Python\Python37\lib\site-packages\waitress\task.py", line 434, in execute
    app_iter = self.channel.server.application(environ, start_response)
  File "C:\Users\Administrador.WIN-DUOGLHGMSST\AppData\Local\Programs\Python\Python37\lib\site-packages\flask\app.py", line 2091, in __call__
    return self.wsgi_app(environ, start_response)
  File "C:\Users\Administrador.WIN-DUOGLHGMSST\AppData\Local\Programs\Python\Python37\lib\site-packages\flask\app.py", line 2076, in wsgi_app
    response = self.handle_exception(e)
  File "C:\Users\Administrador.WIN-DUOGLHGMSST\AppData\Local\Programs\Python\Python37\lib\site-packages\flask\app.py", line 2073, in wsgi_app
    response = self.full_dispatch_request()
  File "C:\Users\Administrador.WIN-DUOGLHGMSST\AppData\Local\Programs\Python\Python37\lib\site-packages\flask\app.py", line 1518, in full_dispatch_request
    rv = self.handle_user_exception(e)
  File "C:\Users\Administrador.WIN-DUOGLHGMSST\AppData\Local\Programs\Python\Python37\lib\site-packages\flask\app.py", line 1516, in full_dispatch_request
    rv = self.dispatch_request()
  File "C:\Users\Administrador.WIN-DUOGLHGMSST\AppData\Local\Programs\Python\Python37\lib\site-packages\flask\app.py", line 1502, in dispatch_request
    return self.ensure_sync(self.view_functions[rule.endpoint])(**req.view_args)
  File "C:\xampp\htdocs\CLANAD_PY\FlaskSecurity\app\src\Actividad.py", line 416, in ver_archivo_por_codigo
    print(e.__class__.__name__)
NameError: name 'e' is not defined
{'TIME':2022-02-04 11:59:06,607,'ADDRESS':'127.0.0.1','URL': 'http://localhost:8001/verArchivo/%2A�����%27�%19�xeĞ��%1FC����%2A�ƌ�b��E�̕e���%7B�G%11ZH��%1A��c%1Em%25�%11-o9Z%1B���9���%3B%1F�ϊEf','TYPE':'ERROR','MODULE':'channel','MSG':{Exception while serving /verArchivo/*ï¿½ï¿½ï¿½ï¿½ï¿½'ï¿½ï¿½xeÄï¿½ï¿½Cï¿½ï¿½ï¿½ï¿½*ï¿½Æï¿½bï¿½ï¿½Eï¿½Ìeï¿½ï¿½ï¿½{ï¿½GZHï¿½ï¿½ï¿½ï¿½cm%ï¿½-o9Zï¿½ï¿½ï¿½9ï¿½ï¿½ï¿½;ï¿½ÏEf}}
Traceback (most recent call last):
  File "C:\xampp\htdocs\CLANAD_PY\FlaskSecurity\app\src\Actividad.py", line 410, in ver_archivo_por_codigo
    if not Path(location).is_file():
NameError: name 'Path' is not defined

During handling of the above exception, another exception occurred:

Traceback (most recent call last):
  File "C:\Users\Administrador.WIN-DUOGLHGMSST\AppData\Local\Programs\Python\Python37\lib\site-packages\waitress\channel.py", line 397, in service
    task.service()
  File "C:\Users\Administrador.WIN-DUOGLHGMSST\AppData\Local\Programs\Python\Python37\lib\site-packages\waitress\task.py", line 168, in service
    self.execute()
  File "C:\Users\Administrador.WIN-DUOGLHGMSST\AppData\Local\Programs\Python\Python37\lib\site-packages\waitress\task.py", line 434, in execute
    app_iter = self.channel.server.application(environ, start_response)
  File "C:\Users\Administrador.WIN-DUOGLHGMSST\AppData\Local\Programs\Python\Python37\lib\site-packages\flask\app.py", line 2091, in __call__
    return self.wsgi_app(environ, start_response)
  File "C:\Users\Administrador.WIN-DUOGLHGMSST\AppData\Local\Programs\Python\Python37\lib\site-packages\flask\app.py", line 2076, in wsgi_app
    response = self.handle_exception(e)
  File "C:\Users\Administrador.WIN-DUOGLHGMSST\AppData\Local\Programs\Python\Python37\lib\site-packages\flask\app.py", line 2073, in wsgi_app
    response = self.full_dispatch_request()
  File "C:\Users\Administrador.WIN-DUOGLHGMSST\AppData\Local\Programs\Python\Python37\lib\site-packages\flask\app.py", line 1518, in full_dispatch_request
    rv = self.handle_user_exception(e)
  File "C:\Users\Administrador.WIN-DUOGLHGMSST\AppData\Local\Programs\Python\Python37\lib\site-packages\flask\app.py", line 1516, in full_dispatch_request
    rv = self.dispatch_request()
  File "C:\Users\Administrador.WIN-DUOGLHGMSST\AppData\Local\Programs\Python\Python37\lib\site-packages\flask\app.py", line 1502, in dispatch_request
    return self.ensure_sync(self.view_functions[rule.endpoint])(**req.view_args)
  File "C:\xampp\htdocs\CLANAD_PY\FlaskSecurity\app\src\Actividad.py", line 416, in ver_archivo_por_codigo
    print(e.__class__.__name__)
NameError: name 'e' is not defined
{'TIME':2022-02-04 13:32:44,188,'ADDRESS':'127.0.0.1','URL': 'http://localhost:8001/test','TYPE':'ERROR','MODULE':'channel','MSG':{Exception while serving /test}}
Traceback (most recent call last):
  File "C:\xampp\htdocs\CLANAD_PY\FlaskSecurity\app\src\Actividad.py", line 395, in codigo_hash
    return jsonify(lccodigo),200
  File "C:\Users\Administrador.WIN-DUOGLHGMSST\AppData\Local\Programs\Python\Python37\lib\site-packages\flask\json\__init__.py", line 355, in jsonify
    f"{dumps(data, indent=indent, separators=separators)}\n",
  File "C:\Users\Administrador.WIN-DUOGLHGMSST\AppData\Local\Programs\Python\Python37\lib\site-packages\flask\json\__init__.py", line 133, in dumps
    rv = _json.dumps(obj, **kwargs)
  File "C:\Users\Administrador.WIN-DUOGLHGMSST\AppData\Local\Programs\Python\Python37\lib\json\__init__.py", line 238, in dumps
    **kw).encode(obj)
  File "C:\Users\Administrador.WIN-DUOGLHGMSST\AppData\Local\Programs\Python\Python37\lib\json\encoder.py", line 201, in encode
    chunks = list(chunks)
  File "C:\Users\Administrador.WIN-DUOGLHGMSST\AppData\Local\Programs\Python\Python37\lib\json\encoder.py", line 438, in _iterencode
    o = _default(o)
  File "C:\Users\Administrador.WIN-DUOGLHGMSST\AppData\Local\Programs\Python\Python37\lib\site-packages\flask\json\__init__.py", line 57, in default
    return super().default(o)
  File "C:\Users\Administrador.WIN-DUOGLHGMSST\AppData\Local\Programs\Python\Python37\lib\json\encoder.py", line 179, in default
    raise TypeError(f'Object of type {o.__class__.__name__} '
TypeError: Object of type bytes is not JSON serializable

During handling of the above exception, another exception occurred:

Traceback (most recent call last):
  File "C:\Users\Administrador.WIN-DUOGLHGMSST\AppData\Local\Programs\Python\Python37\lib\site-packages\waitress\channel.py", line 397, in service
    task.service()
  File "C:\Users\Administrador.WIN-DUOGLHGMSST\AppData\Local\Programs\Python\Python37\lib\site-packages\waitress\task.py", line 168, in service
    self.execute()
  File "C:\Users\Administrador.WIN-DUOGLHGMSST\AppData\Local\Programs\Python\Python37\lib\site-packages\waitress\task.py", line 434, in execute
    app_iter = self.channel.server.application(environ, start_response)
  File "C:\Users\Administrador.WIN-DUOGLHGMSST\AppData\Local\Programs\Python\Python37\lib\site-packages\flask\app.py", line 2091, in __call__
    return self.wsgi_app(environ, start_response)
  File "C:\Users\Administrador.WIN-DUOGLHGMSST\AppData\Local\Programs\Python\Python37\lib\site-packages\flask\app.py", line 2076, in wsgi_app
    response = self.handle_exception(e)
  File "C:\Users\Administrador.WIN-DUOGLHGMSST\AppData\Local\Programs\Python\Python37\lib\site-packages\flask\app.py", line 2073, in wsgi_app
    response = self.full_dispatch_request()
  File "C:\Users\Administrador.WIN-DUOGLHGMSST\AppData\Local\Programs\Python\Python37\lib\site-packages\flask\app.py", line 1518, in full_dispatch_request
    rv = self.handle_user_exception(e)
  File "C:\Users\Administrador.WIN-DUOGLHGMSST\AppData\Local\Programs\Python\Python37\lib\site-packages\flask\app.py", line 1516, in full_dispatch_request
    rv = self.dispatch_request()
  File "C:\Users\Administrador.WIN-DUOGLHGMSST\AppData\Local\Programs\Python\Python37\lib\site-packages\flask\app.py", line 1502, in dispatch_request
    return self.ensure_sync(self.view_functions[rule.endpoint])(**req.view_args)
  File "C:\xampp\htdocs\CLANAD_PY\FlaskSecurity\app\src\Actividad.py", line 397, in codigo_hash
    print(e.__class__.__name__)
NameError: name 'e' is not defined
{'TIME':2022-02-04 13:42:37,134,'ADDRESS':'10.10.150.200','URL': 'http://10.10.110.13:8001/verArchivo','TYPE':'ERROR','MODULE':'channel','MSG':{Exception while serving /verArchivo}}
Traceback (most recent call last):
  File "C:\xampp\htdocs\CLANAD_PY\FlaskSecurity\app\src\Actividad.py", line 405, in ver_archivo_por_codigo
    lcCodigo = request.to_dict()
AttributeError: 'Request' object has no attribute 'to_dict'

During handling of the above exception, another exception occurred:

Traceback (most recent call last):
  File "C:\Users\Administrador.WIN-DUOGLHGMSST\AppData\Local\Programs\Python\Python37\lib\site-packages\waitress\channel.py", line 397, in service
    task.service()
  File "C:\Users\Administrador.WIN-DUOGLHGMSST\AppData\Local\Programs\Python\Python37\lib\site-packages\waitress\task.py", line 168, in service
    self.execute()
  File "C:\Users\Administrador.WIN-DUOGLHGMSST\AppData\Local\Programs\Python\Python37\lib\site-packages\waitress\task.py", line 434, in execute
    app_iter = self.channel.server.application(environ, start_response)
  File "C:\Users\Administrador.WIN-DUOGLHGMSST\AppData\Local\Programs\Python\Python37\lib\site-packages\flask\app.py", line 2091, in __call__
    return self.wsgi_app(environ, start_response)
  File "C:\Users\Administrador.WIN-DUOGLHGMSST\AppData\Local\Programs\Python\Python37\lib\site-packages\flask\app.py", line 2076, in wsgi_app
    response = self.handle_exception(e)
  File "C:\Users\Administrador.WIN-DUOGLHGMSST\AppData\Local\Programs\Python\Python37\lib\site-packages\flask\app.py", line 2073, in wsgi_app
    response = self.full_dispatch_request()
  File "C:\Users\Administrador.WIN-DUOGLHGMSST\AppData\Local\Programs\Python\Python37\lib\site-packages\flask\app.py", line 1518, in full_dispatch_request
    rv = self.handle_user_exception(e)
  File "C:\Users\Administrador.WIN-DUOGLHGMSST\AppData\Local\Programs\Python\Python37\lib\site-packages\flask\app.py", line 1516, in full_dispatch_request
    rv = self.dispatch_request()
  File "C:\Users\Administrador.WIN-DUOGLHGMSST\AppData\Local\Programs\Python\Python37\lib\site-packages\flask\app.py", line 1502, in dispatch_request
    return self.ensure_sync(self.view_functions[rule.endpoint])(**req.view_args)
  File "C:\xampp\htdocs\CLANAD_PY\FlaskSecurity\app\src\Actividad.py", line 416, in ver_archivo_por_codigo
    print(e.__class__.__name__)
NameError: name 'e' is not defined
{'TIME':2022-02-04 13:43:10,106,'ADDRESS':'10.10.150.200','URL': 'http://10.10.110.13:8001/verArchivo','TYPE':'ERROR','MODULE':'channel','MSG':{Exception while serving /verArchivo}}
Traceback (most recent call last):
  File "C:\xampp\htdocs\CLANAD_PY\FlaskSecurity\app\src\Actividad.py", line 406, in ver_archivo_por_codigo
    lcCodigo = request.to_dict()
AttributeError: 'Request' object has no attribute 'to_dict'

During handling of the above exception, another exception occurred:

Traceback (most recent call last):
  File "C:\Users\Administrador.WIN-DUOGLHGMSST\AppData\Local\Programs\Python\Python37\lib\site-packages\waitress\channel.py", line 397, in service
    task.service()
  File "C:\Users\Administrador.WIN-DUOGLHGMSST\AppData\Local\Programs\Python\Python37\lib\site-packages\waitress\task.py", line 168, in service
    self.execute()
  File "C:\Users\Administrador.WIN-DUOGLHGMSST\AppData\Local\Programs\Python\Python37\lib\site-packages\waitress\task.py", line 434, in execute
    app_iter = self.channel.server.application(environ, start_response)
  File "C:\Users\Administrador.WIN-DUOGLHGMSST\AppData\Local\Programs\Python\Python37\lib\site-packages\flask\app.py", line 2091, in __call__
    return self.wsgi_app(environ, start_response)
  File "C:\Users\Administrador.WIN-DUOGLHGMSST\AppData\Local\Programs\Python\Python37\lib\site-packages\flask\app.py", line 2076, in wsgi_app
    response = self.handle_exception(e)
  File "C:\Users\Administrador.WIN-DUOGLHGMSST\AppData\Local\Programs\Python\Python37\lib\site-packages\flask\app.py", line 2073, in wsgi_app
    response = self.full_dispatch_request()
  File "C:\Users\Administrador.WIN-DUOGLHGMSST\AppData\Local\Programs\Python\Python37\lib\site-packages\flask\app.py", line 1518, in full_dispatch_request
    rv = self.handle_user_exception(e)
  File "C:\Users\Administrador.WIN-DUOGLHGMSST\AppData\Local\Programs\Python\Python37\lib\site-packages\flask\app.py", line 1516, in full_dispatch_request
    rv = self.dispatch_request()
  File "C:\Users\Administrador.WIN-DUOGLHGMSST\AppData\Local\Programs\Python\Python37\lib\site-packages\flask\app.py", line 1502, in dispatch_request
    return self.ensure_sync(self.view_functions[rule.endpoint])(**req.view_args)
  File "C:\xampp\htdocs\CLANAD_PY\FlaskSecurity\app\src\Actividad.py", line 417, in ver_archivo_por_codigo
    print(e.__class__.__name__)
NameError: name 'e' is not defined
{'TIME':2022-02-04 13:44:50,378,'ADDRESS':'10.10.150.200','URL': 'http://10.10.110.13:8001/verArchivo','TYPE':'ERROR','MODULE':'channel','MSG':{Exception while serving /verArchivo}}
Traceback (most recent call last):
  File "C:\xampp\htdocs\CLANAD_PY\FlaskSecurity\app\src\Actividad.py", line 411, in ver_archivo_por_codigo
    lcCodigo = request.to_dict()
AttributeError: 'Request' object has no attribute 'to_dict'

During handling of the above exception, another exception occurred:

Traceback (most recent call last):
  File "C:\Users\Administrador.WIN-DUOGLHGMSST\AppData\Local\Programs\Python\Python37\lib\site-packages\waitress\channel.py", line 397, in service
    task.service()
  File "C:\Users\Administrador.WIN-DUOGLHGMSST\AppData\Local\Programs\Python\Python37\lib\site-packages\waitress\task.py", line 168, in service
    self.execute()
  File "C:\Users\Administrador.WIN-DUOGLHGMSST\AppData\Local\Programs\Python\Python37\lib\site-packages\waitress\task.py", line 434, in execute
    app_iter = self.channel.server.application(environ, start_response)
  File "C:\Users\Administrador.WIN-DUOGLHGMSST\AppData\Local\Programs\Python\Python37\lib\site-packages\flask\app.py", line 2091, in __call__
    return self.wsgi_app(environ, start_response)
  File "C:\Users\Administrador.WIN-DUOGLHGMSST\AppData\Local\Programs\Python\Python37\lib\site-packages\flask\app.py", line 2076, in wsgi_app
    response = self.handle_exception(e)
  File "C:\Users\Administrador.WIN-DUOGLHGMSST\AppData\Local\Programs\Python\Python37\lib\site-packages\flask\app.py", line 2073, in wsgi_app
    response = self.full_dispatch_request()
  File "C:\Users\Administrador.WIN-DUOGLHGMSST\AppData\Local\Programs\Python\Python37\lib\site-packages\flask\app.py", line 1518, in full_dispatch_request
    rv = self.handle_user_exception(e)
  File "C:\Users\Administrador.WIN-DUOGLHGMSST\AppData\Local\Programs\Python\Python37\lib\site-packages\flask\app.py", line 1516, in full_dispatch_request
    rv = self.dispatch_request()
  File "C:\Users\Administrador.WIN-DUOGLHGMSST\AppData\Local\Programs\Python\Python37\lib\site-packages\flask\app.py", line 1502, in dispatch_request
    return self.ensure_sync(self.view_functions[rule.endpoint])(**req.view_args)
  File "C:\xampp\htdocs\CLANAD_PY\FlaskSecurity\app\src\Actividad.py", line 422, in ver_archivo_por_codigo
    print(e.__class__.__name__)
NameError: name 'e' is not defined
{'TIME':2022-02-04 13:47:14,623,'ADDRESS':'10.10.150.200','URL': 'http://10.10.110.13:8001/verArchivo','TYPE':'ERROR','MODULE':'channel','MSG':{Exception while serving /verArchivo}}
Traceback (most recent call last):
  File "C:\xampp\htdocs\CLANAD_PY\FlaskSecurity\app\src\Actividad.py", line 408, in ver_archivo_por_codigo
    print(lcCodigo["DATA"])
TypeError: string indices must be integers

During handling of the above exception, another exception occurred:

Traceback (most recent call last):
  File "C:\Users\Administrador.WIN-DUOGLHGMSST\AppData\Local\Programs\Python\Python37\lib\site-packages\waitress\channel.py", line 397, in service
    task.service()
  File "C:\Users\Administrador.WIN-DUOGLHGMSST\AppData\Local\Programs\Python\Python37\lib\site-packages\waitress\task.py", line 168, in service
    self.execute()
  File "C:\Users\Administrador.WIN-DUOGLHGMSST\AppData\Local\Programs\Python\Python37\lib\site-packages\waitress\task.py", line 434, in execute
    app_iter = self.channel.server.application(environ, start_response)
  File "C:\Users\Administrador.WIN-DUOGLHGMSST\AppData\Local\Programs\Python\Python37\lib\site-packages\flask\app.py", line 2091, in __call__
    return self.wsgi_app(environ, start_response)
  File "C:\Users\Administrador.WIN-DUOGLHGMSST\AppData\Local\Programs\Python\Python37\lib\site-packages\flask\app.py", line 2076, in wsgi_app
    response = self.handle_exception(e)
  File "C:\Users\Administrador.WIN-DUOGLHGMSST\AppData\Local\Programs\Python\Python37\lib\site-packages\flask\app.py", line 2073, in wsgi_app
    response = self.full_dispatch_request()
  File "C:\Users\Administrador.WIN-DUOGLHGMSST\AppData\Local\Programs\Python\Python37\lib\site-packages\flask\app.py", line 1518, in full_dispatch_request
    rv = self.handle_user_exception(e)
  File "C:\Users\Administrador.WIN-DUOGLHGMSST\AppData\Local\Programs\Python\Python37\lib\site-packages\flask\app.py", line 1516, in full_dispatch_request
    rv = self.dispatch_request()
  File "C:\Users\Administrador.WIN-DUOGLHGMSST\AppData\Local\Programs\Python\Python37\lib\site-packages\flask\app.py", line 1502, in dispatch_request
    return self.ensure_sync(self.view_functions[rule.endpoint])(**req.view_args)
  File "C:\xampp\htdocs\CLANAD_PY\FlaskSecurity\app\src\Actividad.py", line 418, in ver_archivo_por_codigo
    print(e.__class__.__name__)
NameError: name 'e' is not defined
{'TIME':2022-02-04 13:50:38,858,'ADDRESS':'10.10.150.200','URL': 'http://10.10.110.13:8001/verArchivo','TYPE':'ERROR','MODULE':'channel','MSG':{Exception while serving /verArchivo}}
Traceback (most recent call last):
  File "C:\xampp\htdocs\CLANAD_PY\FlaskSecurity\app\src\Actividad.py", line 408, in ver_archivo_por_codigo
    print(lcCodigo["DATA"])
TypeError: string indices must be integers

During handling of the above exception, another exception occurred:

Traceback (most recent call last):
  File "C:\Users\Administrador.WIN-DUOGLHGMSST\AppData\Local\Programs\Python\Python37\lib\site-packages\waitress\channel.py", line 397, in service
    task.service()
  File "C:\Users\Administrador.WIN-DUOGLHGMSST\AppData\Local\Programs\Python\Python37\lib\site-packages\waitress\task.py", line 168, in service
    self.execute()
  File "C:\Users\Administrador.WIN-DUOGLHGMSST\AppData\Local\Programs\Python\Python37\lib\site-packages\waitress\task.py", line 434, in execute
    app_iter = self.channel.server.application(environ, start_response)
  File "C:\Users\Administrador.WIN-DUOGLHGMSST\AppData\Local\Programs\Python\Python37\lib\site-packages\flask\app.py", line 2091, in __call__
    return self.wsgi_app(environ, start_response)
  File "C:\Users\Administrador.WIN-DUOGLHGMSST\AppData\Local\Programs\Python\Python37\lib\site-packages\flask\app.py", line 2076, in wsgi_app
    response = self.handle_exception(e)
  File "C:\Users\Administrador.WIN-DUOGLHGMSST\AppData\Local\Programs\Python\Python37\lib\site-packages\flask\app.py", line 2073, in wsgi_app
    response = self.full_dispatch_request()
  File "C:\Users\Administrador.WIN-DUOGLHGMSST\AppData\Local\Programs\Python\Python37\lib\site-packages\flask\app.py", line 1518, in full_dispatch_request
    rv = self.handle_user_exception(e)
  File "C:\Users\Administrador.WIN-DUOGLHGMSST\AppData\Local\Programs\Python\Python37\lib\site-packages\flask\app.py", line 1516, in full_dispatch_request
    rv = self.dispatch_request()
  File "C:\Users\Administrador.WIN-DUOGLHGMSST\AppData\Local\Programs\Python\Python37\lib\site-packages\flask\app.py", line 1502, in dispatch_request
    return self.ensure_sync(self.view_functions[rule.endpoint])(**req.view_args)
  File "C:\xampp\htdocs\CLANAD_PY\FlaskSecurity\app\src\Actividad.py", line 418, in ver_archivo_por_codigo
    print(e.__class__.__name__)
NameError: name 'e' is not defined
{'TIME':2022-02-04 13:52:28,134,'ADDRESS':'10.10.150.200','URL': 'http://10.10.110.13:8001/verArchivo','TYPE':'ERROR','MODULE':'channel','MSG':{Exception while serving /verArchivo}}
Traceback (most recent call last):
  File "C:\xampp\htdocs\CLANAD_PY\FlaskSecurity\app\src\Actividad.py", line 408, in ver_archivo_por_codigo
    if not Path(location).is_file():
NameError: name 'Path' is not defined

During handling of the above exception, another exception occurred:

Traceback (most recent call last):
  File "C:\Users\Administrador.WIN-DUOGLHGMSST\AppData\Local\Programs\Python\Python37\lib\site-packages\waitress\channel.py", line 397, in service
    task.service()
  File "C:\Users\Administrador.WIN-DUOGLHGMSST\AppData\Local\Programs\Python\Python37\lib\site-packages\waitress\task.py", line 168, in service
    self.execute()
  File "C:\Users\Administrador.WIN-DUOGLHGMSST\AppData\Local\Programs\Python\Python37\lib\site-packages\waitress\task.py", line 434, in execute
    app_iter = self.channel.server.application(environ, start_response)
  File "C:\Users\Administrador.WIN-DUOGLHGMSST\AppData\Local\Programs\Python\Python37\lib\site-packages\flask\app.py", line 2091, in __call__
    return self.wsgi_app(environ, start_response)
  File "C:\Users\Administrador.WIN-DUOGLHGMSST\AppData\Local\Programs\Python\Python37\lib\site-packages\flask\app.py", line 2076, in wsgi_app
    response = self.handle_exception(e)
  File "C:\Users\Administrador.WIN-DUOGLHGMSST\AppData\Local\Programs\Python\Python37\lib\site-packages\flask\app.py", line 2073, in wsgi_app
    response = self.full_dispatch_request()
  File "C:\Users\Administrador.WIN-DUOGLHGMSST\AppData\Local\Programs\Python\Python37\lib\site-packages\flask\app.py", line 1518, in full_dispatch_request
    rv = self.handle_user_exception(e)
  File "C:\Users\Administrador.WIN-DUOGLHGMSST\AppData\Local\Programs\Python\Python37\lib\site-packages\flask\app.py", line 1516, in full_dispatch_request
    rv = self.dispatch_request()
  File "C:\Users\Administrador.WIN-DUOGLHGMSST\AppData\Local\Programs\Python\Python37\lib\site-packages\flask\app.py", line 1502, in dispatch_request
    return self.ensure_sync(self.view_functions[rule.endpoint])(**req.view_args)
  File "C:\xampp\htdocs\CLANAD_PY\FlaskSecurity\app\src\Actividad.py", line 414, in ver_archivo_por_codigo
    print(e.__class__.__name__)
NameError: name 'e' is not defined
{'TIME':2022-02-04 13:58:47,091,'ADDRESS':'10.10.150.200','URL': 'http://10.10.110.13:8001/verArchivo','TYPE':'ERROR','MODULE':'channel','MSG':{Exception while serving /verArchivo}}
Traceback (most recent call last):
  File "C:\xampp\htdocs\CLANAD_PY\FlaskSecurity\app\src\Actividad.py", line 408, in ver_archivo_por_codigo
    if not Path(location).is_file():
NameError: name 'Path' is not defined

During handling of the above exception, another exception occurred:

Traceback (most recent call last):
  File "C:\Users\Administrador.WIN-DUOGLHGMSST\AppData\Local\Programs\Python\Python37\lib\site-packages\waitress\channel.py", line 397, in service
    task.service()
  File "C:\Users\Administrador.WIN-DUOGLHGMSST\AppData\Local\Programs\Python\Python37\lib\site-packages\waitress\task.py", line 168, in service
    self.execute()
  File "C:\Users\Administrador.WIN-DUOGLHGMSST\AppData\Local\Programs\Python\Python37\lib\site-packages\waitress\task.py", line 434, in execute
    app_iter = self.channel.server.application(environ, start_response)
  File "C:\Users\Administrador.WIN-DUOGLHGMSST\AppData\Local\Programs\Python\Python37\lib\site-packages\flask\app.py", line 2091, in __call__
    return self.wsgi_app(environ, start_response)
  File "C:\Users\Administrador.WIN-DUOGLHGMSST\AppData\Local\Programs\Python\Python37\lib\site-packages\flask\app.py", line 2076, in wsgi_app
    response = self.handle_exception(e)
  File "C:\Users\Administrador.WIN-DUOGLHGMSST\AppData\Local\Programs\Python\Python37\lib\site-packages\flask\app.py", line 2073, in wsgi_app
    response = self.full_dispatch_request()
  File "C:\Users\Administrador.WIN-DUOGLHGMSST\AppData\Local\Programs\Python\Python37\lib\site-packages\flask\app.py", line 1518, in full_dispatch_request
    rv = self.handle_user_exception(e)
  File "C:\Users\Administrador.WIN-DUOGLHGMSST\AppData\Local\Programs\Python\Python37\lib\site-packages\flask\app.py", line 1516, in full_dispatch_request
    rv = self.dispatch_request()
  File "C:\Users\Administrador.WIN-DUOGLHGMSST\AppData\Local\Programs\Python\Python37\lib\site-packages\flask\app.py", line 1502, in dispatch_request
    return self.ensure_sync(self.view_functions[rule.endpoint])(**req.view_args)
  File "C:\xampp\htdocs\CLANAD_PY\FlaskSecurity\app\src\Actividad.py", line 414, in ver_archivo_por_codigo
    print(e.__class__.__name__)
NameError: name 'e' is not defined
{'TIME':2022-02-04 14:00:36,557,'ADDRESS':'10.10.150.200','URL': 'http://10.10.110.13:8001/verArchivo','TYPE':'ERROR','MODULE':'channel','MSG':{Exception while serving /verArchivo}}
Traceback (most recent call last):
  File "C:\xampp\htdocs\CLANAD_PY\FlaskSecurity\app\src\Actividad.py", line 408, in ver_archivo_por_codigo
    if not Path(location).is_file():
NameError: name 'Path' is not defined

During handling of the above exception, another exception occurred:

Traceback (most recent call last):
  File "C:\Users\Administrador.WIN-DUOGLHGMSST\AppData\Local\Programs\Python\Python37\lib\site-packages\waitress\channel.py", line 397, in service
    task.service()
  File "C:\Users\Administrador.WIN-DUOGLHGMSST\AppData\Local\Programs\Python\Python37\lib\site-packages\waitress\task.py", line 168, in service
    self.execute()
  File "C:\Users\Administrador.WIN-DUOGLHGMSST\AppData\Local\Programs\Python\Python37\lib\site-packages\waitress\task.py", line 434, in execute
    app_iter = self.channel.server.application(environ, start_response)
  File "C:\Users\Administrador.WIN-DUOGLHGMSST\AppData\Local\Programs\Python\Python37\lib\site-packages\flask\app.py", line 2091, in __call__
    return self.wsgi_app(environ, start_response)
  File "C:\Users\Administrador.WIN-DUOGLHGMSST\AppData\Local\Programs\Python\Python37\lib\site-packages\flask\app.py", line 2076, in wsgi_app
    response = self.handle_exception(e)
  File "C:\Users\Administrador.WIN-DUOGLHGMSST\AppData\Local\Programs\Python\Python37\lib\site-packages\flask\app.py", line 2073, in wsgi_app
    response = self.full_dispatch_request()
  File "C:\Users\Administrador.WIN-DUOGLHGMSST\AppData\Local\Programs\Python\Python37\lib\site-packages\flask\app.py", line 1518, in full_dispatch_request
    rv = self.handle_user_exception(e)
  File "C:\Users\Administrador.WIN-DUOGLHGMSST\AppData\Local\Programs\Python\Python37\lib\site-packages\flask\app.py", line 1516, in full_dispatch_request
    rv = self.dispatch_request()
  File "C:\Users\Administrador.WIN-DUOGLHGMSST\AppData\Local\Programs\Python\Python37\lib\site-packages\flask\app.py", line 1502, in dispatch_request
    return self.ensure_sync(self.view_functions[rule.endpoint])(**req.view_args)
  File "C:\xampp\htdocs\CLANAD_PY\FlaskSecurity\app\src\Actividad.py", line 414, in ver_archivo_por_codigo
    print(e.__class__.__name__)
NameError: name 'e' is not defined
{'TIME':2022-02-04 14:01:55,752,'ADDRESS':'10.10.150.200','URL': 'http://10.10.110.13:8001/verArchivo','TYPE':'ERROR','MODULE':'channel','MSG':{Exception while serving /verArchivo}}
Traceback (most recent call last):
  File "C:\xampp\htdocs\CLANAD_PY\FlaskSecurity\app\src\Actividad.py", line 408, in ver_archivo_por_codigo
    if not Path(location).is_file():
NameError: name 'Path' is not defined

During handling of the above exception, another exception occurred:

Traceback (most recent call last):
  File "C:\Users\Administrador.WIN-DUOGLHGMSST\AppData\Local\Programs\Python\Python37\lib\site-packages\waitress\channel.py", line 397, in service
    task.service()
  File "C:\Users\Administrador.WIN-DUOGLHGMSST\AppData\Local\Programs\Python\Python37\lib\site-packages\waitress\task.py", line 168, in service
    self.execute()
  File "C:\Users\Administrador.WIN-DUOGLHGMSST\AppData\Local\Programs\Python\Python37\lib\site-packages\waitress\task.py", line 434, in execute
    app_iter = self.channel.server.application(environ, start_response)
  File "C:\Users\Administrador.WIN-DUOGLHGMSST\AppData\Local\Programs\Python\Python37\lib\site-packages\flask\app.py", line 2091, in __call__
    return self.wsgi_app(environ, start_response)
  File "C:\Users\Administrador.WIN-DUOGLHGMSST\AppData\Local\Programs\Python\Python37\lib\site-packages\flask\app.py", line 2076, in wsgi_app
    response = self.handle_exception(e)
  File "C:\Users\Administrador.WIN-DUOGLHGMSST\AppData\Local\Programs\Python\Python37\lib\site-packages\flask\app.py", line 2073, in wsgi_app
    response = self.full_dispatch_request()
  File "C:\Users\Administrador.WIN-DUOGLHGMSST\AppData\Local\Programs\Python\Python37\lib\site-packages\flask\app.py", line 1518, in full_dispatch_request
    rv = self.handle_user_exception(e)
  File "C:\Users\Administrador.WIN-DUOGLHGMSST\AppData\Local\Programs\Python\Python37\lib\site-packages\flask\app.py", line 1516, in full_dispatch_request
    rv = self.dispatch_request()
  File "C:\Users\Administrador.WIN-DUOGLHGMSST\AppData\Local\Programs\Python\Python37\lib\site-packages\flask\app.py", line 1502, in dispatch_request
    return self.ensure_sync(self.view_functions[rule.endpoint])(**req.view_args)
  File "C:\xampp\htdocs\CLANAD_PY\FlaskSecurity\app\src\Actividad.py", line 414, in ver_archivo_por_codigo
    print(e.__class__.__name__)
NameError: name 'e' is not defined
{'TIME':2022-02-04 15:09:36,563,'ADDRESS':'10.10.150.200','URL': 'http://10.10.110.13:8001/verArchivo','TYPE':'ERROR','MODULE':'channel','MSG':{Exception while serving /verArchivo}}
Traceback (most recent call last):
  File "C:\xampp\htdocs\CLANAD_PY\FlaskSecurity\app\src\Actividad.py", line 408, in ver_archivo_por_codigo
    if not Path(location).is_file():
NameError: name 'Path' is not defined

During handling of the above exception, another exception occurred:

Traceback (most recent call last):
  File "C:\Users\Administrador.WIN-DUOGLHGMSST\AppData\Local\Programs\Python\Python37\lib\site-packages\waitress\channel.py", line 397, in service
    task.service()
  File "C:\Users\Administrador.WIN-DUOGLHGMSST\AppData\Local\Programs\Python\Python37\lib\site-packages\waitress\task.py", line 168, in service
    self.execute()
  File "C:\Users\Administrador.WIN-DUOGLHGMSST\AppData\Local\Programs\Python\Python37\lib\site-packages\waitress\task.py", line 434, in execute
    app_iter = self.channel.server.application(environ, start_response)
  File "C:\Users\Administrador.WIN-DUOGLHGMSST\AppData\Local\Programs\Python\Python37\lib\site-packages\flask\app.py", line 2091, in __call__
    return self.wsgi_app(environ, start_response)
  File "C:\Users\Administrador.WIN-DUOGLHGMSST\AppData\Local\Programs\Python\Python37\lib\site-packages\flask\app.py", line 2076, in wsgi_app
    response = self.handle_exception(e)
  File "C:\Users\Administrador.WIN-DUOGLHGMSST\AppData\Local\Programs\Python\Python37\lib\site-packages\flask\app.py", line 2073, in wsgi_app
    response = self.full_dispatch_request()
  File "C:\Users\Administrador.WIN-DUOGLHGMSST\AppData\Local\Programs\Python\Python37\lib\site-packages\flask\app.py", line 1518, in full_dispatch_request
    rv = self.handle_user_exception(e)
  File "C:\Users\Administrador.WIN-DUOGLHGMSST\AppData\Local\Programs\Python\Python37\lib\site-packages\flask\app.py", line 1516, in full_dispatch_request
    rv = self.dispatch_request()
  File "C:\Users\Administrador.WIN-DUOGLHGMSST\AppData\Local\Programs\Python\Python37\lib\site-packages\flask\app.py", line 1502, in dispatch_request
    return self.ensure_sync(self.view_functions[rule.endpoint])(**req.view_args)
  File "C:\xampp\htdocs\CLANAD_PY\FlaskSecurity\app\src\Actividad.py", line 414, in ver_archivo_por_codigo
    print(e.__class__.__name__)
NameError: name 'e' is not defined
{'TIME':2022-02-04 15:11:19,645,'ADDRESS':'10.10.150.200','URL': 'http://10.10.110.13:8001/verArchivo','TYPE':'ERROR','MODULE':'channel','MSG':{Exception while serving /verArchivo}}
Traceback (most recent call last):
  File "C:\xampp\htdocs\CLANAD_PY\FlaskSecurity\app\src\Actividad.py", line 408, in ver_archivo_por_codigo
    if not Path(location).is_file():
NameError: name 'Path' is not defined

During handling of the above exception, another exception occurred:

Traceback (most recent call last):
  File "C:\Users\Administrador.WIN-DUOGLHGMSST\AppData\Local\Programs\Python\Python37\lib\site-packages\waitress\channel.py", line 397, in service
    task.service()
  File "C:\Users\Administrador.WIN-DUOGLHGMSST\AppData\Local\Programs\Python\Python37\lib\site-packages\waitress\task.py", line 168, in service
    self.execute()
  File "C:\Users\Administrador.WIN-DUOGLHGMSST\AppData\Local\Programs\Python\Python37\lib\site-packages\waitress\task.py", line 434, in execute
    app_iter = self.channel.server.application(environ, start_response)
  File "C:\Users\Administrador.WIN-DUOGLHGMSST\AppData\Local\Programs\Python\Python37\lib\site-packages\flask\app.py", line 2091, in __call__
    return self.wsgi_app(environ, start_response)
  File "C:\Users\Administrador.WIN-DUOGLHGMSST\AppData\Local\Programs\Python\Python37\lib\site-packages\flask\app.py", line 2076, in wsgi_app
    response = self.handle_exception(e)
  File "C:\Users\Administrador.WIN-DUOGLHGMSST\AppData\Local\Programs\Python\Python37\lib\site-packages\flask\app.py", line 2073, in wsgi_app
    response = self.full_dispatch_request()
  File "C:\Users\Administrador.WIN-DUOGLHGMSST\AppData\Local\Programs\Python\Python37\lib\site-packages\flask\app.py", line 1518, in full_dispatch_request
    rv = self.handle_user_exception(e)
  File "C:\Users\Administrador.WIN-DUOGLHGMSST\AppData\Local\Programs\Python\Python37\lib\site-packages\flask\app.py", line 1516, in full_dispatch_request
    rv = self.dispatch_request()
  File "C:\Users\Administrador.WIN-DUOGLHGMSST\AppData\Local\Programs\Python\Python37\lib\site-packages\flask\app.py", line 1502, in dispatch_request
    return self.ensure_sync(self.view_functions[rule.endpoint])(**req.view_args)
  File "C:\xampp\htdocs\CLANAD_PY\FlaskSecurity\app\src\Actividad.py", line 414, in ver_archivo_por_codigo
    print(e.__class__.__name__)
NameError: name 'e' is not defined
{'TIME':2022-02-04 15:11:52,155,'ADDRESS':'10.10.150.200','URL': 'http://10.10.110.13:8001/verArchivo','TYPE':'ERROR','MODULE':'channel','MSG':{Exception while serving /verArchivo}}
Traceback (most recent call last):
  File "C:\xampp\htdocs\CLANAD_PY\FlaskSecurity\app\src\Actividad.py", line 408, in ver_archivo_por_codigo
    if not Path(location).is_file():
NameError: name 'Path' is not defined

During handling of the above exception, another exception occurred:

Traceback (most recent call last):
  File "C:\Users\Administrador.WIN-DUOGLHGMSST\AppData\Local\Programs\Python\Python37\lib\site-packages\waitress\channel.py", line 397, in service
    task.service()
  File "C:\Users\Administrador.WIN-DUOGLHGMSST\AppData\Local\Programs\Python\Python37\lib\site-packages\waitress\task.py", line 168, in service
    self.execute()
  File "C:\Users\Administrador.WIN-DUOGLHGMSST\AppData\Local\Programs\Python\Python37\lib\site-packages\waitress\task.py", line 434, in execute
    app_iter = self.channel.server.application(environ, start_response)
  File "C:\Users\Administrador.WIN-DUOGLHGMSST\AppData\Local\Programs\Python\Python37\lib\site-packages\flask\app.py", line 2091, in __call__
    return self.wsgi_app(environ, start_response)
  File "C:\Users\Administrador.WIN-DUOGLHGMSST\AppData\Local\Programs\Python\Python37\lib\site-packages\flask\app.py", line 2076, in wsgi_app
    response = self.handle_exception(e)
  File "C:\Users\Administrador.WIN-DUOGLHGMSST\AppData\Local\Programs\Python\Python37\lib\site-packages\flask\app.py", line 2073, in wsgi_app
    response = self.full_dispatch_request()
  File "C:\Users\Administrador.WIN-DUOGLHGMSST\AppData\Local\Programs\Python\Python37\lib\site-packages\flask\app.py", line 1518, in full_dispatch_request
    rv = self.handle_user_exception(e)
  File "C:\Users\Administrador.WIN-DUOGLHGMSST\AppData\Local\Programs\Python\Python37\lib\site-packages\flask\app.py", line 1516, in full_dispatch_request
    rv = self.dispatch_request()
  File "C:\Users\Administrador.WIN-DUOGLHGMSST\AppData\Local\Programs\Python\Python37\lib\site-packages\flask\app.py", line 1502, in dispatch_request
    return self.ensure_sync(self.view_functions[rule.endpoint])(**req.view_args)
  File "C:\xampp\htdocs\CLANAD_PY\FlaskSecurity\app\src\Actividad.py", line 414, in ver_archivo_por_codigo
    print(e.__class__.__name__)
NameError: name 'e' is not defined
{'TIME':2022-02-04 15:31:48,391,'ADDRESS':'10.10.150.200','URL': 'http://10.10.110.13:8001/verArchivo','TYPE':'ERROR','MODULE':'channel','MSG':{Exception while serving /verArchivo}}
Traceback (most recent call last):
  File "C:\xampp\htdocs\CLANAD_PY\FlaskSecurity\app\src\Actividad.py", line 408, in ver_archivo_por_codigo
    if not Path(location).is_file():
NameError: name 'Path' is not defined

During handling of the above exception, another exception occurred:

Traceback (most recent call last):
  File "C:\Users\Administrador.WIN-DUOGLHGMSST\AppData\Local\Programs\Python\Python37\lib\site-packages\waitress\channel.py", line 397, in service
    task.service()
  File "C:\Users\Administrador.WIN-DUOGLHGMSST\AppData\Local\Programs\Python\Python37\lib\site-packages\waitress\task.py", line 168, in service
    self.execute()
  File "C:\Users\Administrador.WIN-DUOGLHGMSST\AppData\Local\Programs\Python\Python37\lib\site-packages\waitress\task.py", line 434, in execute
    app_iter = self.channel.server.application(environ, start_response)
  File "C:\Users\Administrador.WIN-DUOGLHGMSST\AppData\Local\Programs\Python\Python37\lib\site-packages\flask\app.py", line 2091, in __call__
    return self.wsgi_app(environ, start_response)
  File "C:\Users\Administrador.WIN-DUOGLHGMSST\AppData\Local\Programs\Python\Python37\lib\site-packages\flask\app.py", line 2076, in wsgi_app
    response = self.handle_exception(e)
  File "C:\Users\Administrador.WIN-DUOGLHGMSST\AppData\Local\Programs\Python\Python37\lib\site-packages\flask\app.py", line 2073, in wsgi_app
    response = self.full_dispatch_request()
  File "C:\Users\Administrador.WIN-DUOGLHGMSST\AppData\Local\Programs\Python\Python37\lib\site-packages\flask\app.py", line 1518, in full_dispatch_request
    rv = self.handle_user_exception(e)
  File "C:\Users\Administrador.WIN-DUOGLHGMSST\AppData\Local\Programs\Python\Python37\lib\site-packages\flask\app.py", line 1516, in full_dispatch_request
    rv = self.dispatch_request()
  File "C:\Users\Administrador.WIN-DUOGLHGMSST\AppData\Local\Programs\Python\Python37\lib\site-packages\flask\app.py", line 1502, in dispatch_request
    return self.ensure_sync(self.view_functions[rule.endpoint])(**req.view_args)
  File "C:\xampp\htdocs\CLANAD_PY\FlaskSecurity\app\src\Actividad.py", line 414, in ver_archivo_por_codigo
    print(e.__class__.__name__)
NameError: name 'e' is not defined
{'TIME':2022-02-04 15:33:41,832,'ADDRESS':'10.10.150.200','URL': 'http://10.10.110.13:8001/verArchivo','TYPE':'ERROR','MODULE':'channel','MSG':{Exception while serving /verArchivo}}
Traceback (most recent call last):
  File "C:\xampp\htdocs\CLANAD_PY\FlaskSecurity\app\src\Actividad.py", line 408, in ver_archivo_por_codigo
    if not Path(location).is_file():
NameError: name 'Path' is not defined

During handling of the above exception, another exception occurred:

Traceback (most recent call last):
  File "C:\Users\Administrador.WIN-DUOGLHGMSST\AppData\Local\Programs\Python\Python37\lib\site-packages\waitress\channel.py", line 397, in service
    task.service()
  File "C:\Users\Administrador.WIN-DUOGLHGMSST\AppData\Local\Programs\Python\Python37\lib\site-packages\waitress\task.py", line 168, in service
    self.execute()
  File "C:\Users\Administrador.WIN-DUOGLHGMSST\AppData\Local\Programs\Python\Python37\lib\site-packages\waitress\task.py", line 434, in execute
    app_iter = self.channel.server.application(environ, start_response)
  File "C:\Users\Administrador.WIN-DUOGLHGMSST\AppData\Local\Programs\Python\Python37\lib\site-packages\flask\app.py", line 2091, in __call__
    return self.wsgi_app(environ, start_response)
  File "C:\Users\Administrador.WIN-DUOGLHGMSST\AppData\Local\Programs\Python\Python37\lib\site-packages\flask\app.py", line 2076, in wsgi_app
    response = self.handle_exception(e)
  File "C:\Users\Administrador.WIN-DUOGLHGMSST\AppData\Local\Programs\Python\Python37\lib\site-packages\flask\app.py", line 2073, in wsgi_app
    response = self.full_dispatch_request()
  File "C:\Users\Administrador.WIN-DUOGLHGMSST\AppData\Local\Programs\Python\Python37\lib\site-packages\flask\app.py", line 1518, in full_dispatch_request
    rv = self.handle_user_exception(e)
  File "C:\Users\Administrador.WIN-DUOGLHGMSST\AppData\Local\Programs\Python\Python37\lib\site-packages\flask\app.py", line 1516, in full_dispatch_request
    rv = self.dispatch_request()
  File "C:\Users\Administrador.WIN-DUOGLHGMSST\AppData\Local\Programs\Python\Python37\lib\site-packages\flask\app.py", line 1502, in dispatch_request
    return self.ensure_sync(self.view_functions[rule.endpoint])(**req.view_args)
  File "C:\xampp\htdocs\CLANAD_PY\FlaskSecurity\app\src\Actividad.py", line 414, in ver_archivo_por_codigo
    print(e.__class__.__name__)
NameError: name 'e' is not defined
{'TIME':2022-02-04 15:34:10,971,'ADDRESS':'10.10.150.200','URL': 'http://10.10.110.13:8001/verArchivo','TYPE':'ERROR','MODULE':'channel','MSG':{Exception while serving /verArchivo}}
Traceback (most recent call last):
  File "C:\xampp\htdocs\CLANAD_PY\FlaskSecurity\app\src\Actividad.py", line 408, in ver_archivo_por_codigo
    if not Path(location).is_file():
NameError: name 'Path' is not defined

During handling of the above exception, another exception occurred:

Traceback (most recent call last):
  File "C:\Users\Administrador.WIN-DUOGLHGMSST\AppData\Local\Programs\Python\Python37\lib\site-packages\waitress\channel.py", line 397, in service
    task.service()
  File "C:\Users\Administrador.WIN-DUOGLHGMSST\AppData\Local\Programs\Python\Python37\lib\site-packages\waitress\task.py", line 168, in service
    self.execute()
  File "C:\Users\Administrador.WIN-DUOGLHGMSST\AppData\Local\Programs\Python\Python37\lib\site-packages\waitress\task.py", line 434, in execute
    app_iter = self.channel.server.application(environ, start_response)
  File "C:\Users\Administrador.WIN-DUOGLHGMSST\AppData\Local\Programs\Python\Python37\lib\site-packages\flask\app.py", line 2091, in __call__
    return self.wsgi_app(environ, start_response)
  File "C:\Users\Administrador.WIN-DUOGLHGMSST\AppData\Local\Programs\Python\Python37\lib\site-packages\flask\app.py", line 2076, in wsgi_app
    response = self.handle_exception(e)
  File "C:\Users\Administrador.WIN-DUOGLHGMSST\AppData\Local\Programs\Python\Python37\lib\site-packages\flask\app.py", line 2073, in wsgi_app
    response = self.full_dispatch_request()
  File "C:\Users\Administrador.WIN-DUOGLHGMSST\AppData\Local\Programs\Python\Python37\lib\site-packages\flask\app.py", line 1518, in full_dispatch_request
    rv = self.handle_user_exception(e)
  File "C:\Users\Administrador.WIN-DUOGLHGMSST\AppData\Local\Programs\Python\Python37\lib\site-packages\flask\app.py", line 1516, in full_dispatch_request
    rv = self.dispatch_request()
  File "C:\Users\Administrador.WIN-DUOGLHGMSST\AppData\Local\Programs\Python\Python37\lib\site-packages\flask\app.py", line 1502, in dispatch_request
    return self.ensure_sync(self.view_functions[rule.endpoint])(**req.view_args)
  File "C:\xampp\htdocs\CLANAD_PY\FlaskSecurity\app\src\Actividad.py", line 414, in ver_archivo_por_codigo
    print(e.__class__.__name__)
NameError: name 'e' is not defined
{'TIME':2022-02-04 15:35:10,939,'ADDRESS':'10.10.150.200','URL': 'http://10.10.110.13:8001/verArchivo','TYPE':'ERROR','MODULE':'channel','MSG':{Exception while serving /verArchivo}}
Traceback (most recent call last):
  File "C:\xampp\htdocs\CLANAD_PY\FlaskSecurity\app\src\Actividad.py", line 408, in ver_archivo_por_codigo
    if not Path(location).is_file():
NameError: name 'Path' is not defined

During handling of the above exception, another exception occurred:

Traceback (most recent call last):
  File "C:\Users\Administrador.WIN-DUOGLHGMSST\AppData\Local\Programs\Python\Python37\lib\site-packages\waitress\channel.py", line 397, in service
    task.service()
  File "C:\Users\Administrador.WIN-DUOGLHGMSST\AppData\Local\Programs\Python\Python37\lib\site-packages\waitress\task.py", line 168, in service
    self.execute()
  File "C:\Users\Administrador.WIN-DUOGLHGMSST\AppData\Local\Programs\Python\Python37\lib\site-packages\waitress\task.py", line 434, in execute
    app_iter = self.channel.server.application(environ, start_response)
  File "C:\Users\Administrador.WIN-DUOGLHGMSST\AppData\Local\Programs\Python\Python37\lib\site-packages\flask\app.py", line 2091, in __call__
    return self.wsgi_app(environ, start_response)
  File "C:\Users\Administrador.WIN-DUOGLHGMSST\AppData\Local\Programs\Python\Python37\lib\site-packages\flask\app.py", line 2076, in wsgi_app
    response = self.handle_exception(e)
  File "C:\Users\Administrador.WIN-DUOGLHGMSST\AppData\Local\Programs\Python\Python37\lib\site-packages\flask\app.py", line 2073, in wsgi_app
    response = self.full_dispatch_request()
  File "C:\Users\Administrador.WIN-DUOGLHGMSST\AppData\Local\Programs\Python\Python37\lib\site-packages\flask\app.py", line 1518, in full_dispatch_request
    rv = self.handle_user_exception(e)
  File "C:\Users\Administrador.WIN-DUOGLHGMSST\AppData\Local\Programs\Python\Python37\lib\site-packages\flask\app.py", line 1516, in full_dispatch_request
    rv = self.dispatch_request()
  File "C:\Users\Administrador.WIN-DUOGLHGMSST\AppData\Local\Programs\Python\Python37\lib\site-packages\flask\app.py", line 1502, in dispatch_request
    return self.ensure_sync(self.view_functions[rule.endpoint])(**req.view_args)
  File "C:\xampp\htdocs\CLANAD_PY\FlaskSecurity\app\src\Actividad.py", line 414, in ver_archivo_por_codigo
    print(e.__class__.__name__)
NameError: name 'e' is not defined
{'TIME':2022-02-04 15:37:22,533,'ADDRESS':'127.0.0.1','URL': 'http://localhost:8001/test','TYPE':'ERROR','MODULE':'channel','MSG':{Exception while serving /test}}
Traceback (most recent call last):
  File "C:\xampp\htdocs\CLANAD_PY\FlaskSecurity\app\src\Actividad.py", line 394, in codigo_hash
    return jsonify({"OK":1,"DATA":lccodigo}),200
  File "C:\Users\Administrador.WIN-DUOGLHGMSST\AppData\Local\Programs\Python\Python37\lib\site-packages\flask\json\__init__.py", line 355, in jsonify
    f"{dumps(data, indent=indent, separators=separators)}\n",
  File "C:\Users\Administrador.WIN-DUOGLHGMSST\AppData\Local\Programs\Python\Python37\lib\site-packages\flask\json\__init__.py", line 133, in dumps
    rv = _json.dumps(obj, **kwargs)
  File "C:\Users\Administrador.WIN-DUOGLHGMSST\AppData\Local\Programs\Python\Python37\lib\json\__init__.py", line 238, in dumps
    **kw).encode(obj)
  File "C:\Users\Administrador.WIN-DUOGLHGMSST\AppData\Local\Programs\Python\Python37\lib\json\encoder.py", line 201, in encode
    chunks = list(chunks)
  File "C:\Users\Administrador.WIN-DUOGLHGMSST\AppData\Local\Programs\Python\Python37\lib\json\encoder.py", line 431, in _iterencode
    yield from _iterencode_dict(o, _current_indent_level)
  File "C:\Users\Administrador.WIN-DUOGLHGMSST\AppData\Local\Programs\Python\Python37\lib\json\encoder.py", line 405, in _iterencode_dict
    yield from chunks
  File "C:\Users\Administrador.WIN-DUOGLHGMSST\AppData\Local\Programs\Python\Python37\lib\json\encoder.py", line 438, in _iterencode
    o = _default(o)
  File "C:\Users\Administrador.WIN-DUOGLHGMSST\AppData\Local\Programs\Python\Python37\lib\site-packages\flask\json\__init__.py", line 57, in default
    return super().default(o)
  File "C:\Users\Administrador.WIN-DUOGLHGMSST\AppData\Local\Programs\Python\Python37\lib\json\encoder.py", line 179, in default
    raise TypeError(f'Object of type {o.__class__.__name__} '
TypeError: Object of type bytes is not JSON serializable

During handling of the above exception, another exception occurred:

Traceback (most recent call last):
  File "C:\Users\Administrador.WIN-DUOGLHGMSST\AppData\Local\Programs\Python\Python37\lib\site-packages\waitress\channel.py", line 397, in service
    task.service()
  File "C:\Users\Administrador.WIN-DUOGLHGMSST\AppData\Local\Programs\Python\Python37\lib\site-packages\waitress\task.py", line 168, in service
    self.execute()
  File "C:\Users\Administrador.WIN-DUOGLHGMSST\AppData\Local\Programs\Python\Python37\lib\site-packages\waitress\task.py", line 434, in execute
    app_iter = self.channel.server.application(environ, start_response)
  File "C:\Users\Administrador.WIN-DUOGLHGMSST\AppData\Local\Programs\Python\Python37\lib\site-packages\flask\app.py", line 2091, in __call__
    return self.wsgi_app(environ, start_response)
  File "C:\Users\Administrador.WIN-DUOGLHGMSST\AppData\Local\Programs\Python\Python37\lib\site-packages\flask\app.py", line 2076, in wsgi_app
    response = self.handle_exception(e)
  File "C:\Users\Administrador.WIN-DUOGLHGMSST\AppData\Local\Programs\Python\Python37\lib\site-packages\flask\app.py", line 2073, in wsgi_app
    response = self.full_dispatch_request()
  File "C:\Users\Administrador.WIN-DUOGLHGMSST\AppData\Local\Programs\Python\Python37\lib\site-packages\flask\app.py", line 1518, in full_dispatch_request
    rv = self.handle_user_exception(e)
  File "C:\Users\Administrador.WIN-DUOGLHGMSST\AppData\Local\Programs\Python\Python37\lib\site-packages\flask\app.py", line 1516, in full_dispatch_request
    rv = self.dispatch_request()
  File "C:\Users\Administrador.WIN-DUOGLHGMSST\AppData\Local\Programs\Python\Python37\lib\site-packages\flask\app.py", line 1502, in dispatch_request
    return self.ensure_sync(self.view_functions[rule.endpoint])(**req.view_args)
  File "C:\xampp\htdocs\CLANAD_PY\FlaskSecurity\app\src\Actividad.py", line 396, in codigo_hash
    print(e.__class__.__name__)
NameError: name 'e' is not defined
{'TIME':2022-02-04 15:49:51,186,'ADDRESS':'10.10.150.200','URL': 'http://10.10.110.13:8001/verArchivo','TYPE':'ERROR','MODULE':'channel','MSG':{Exception while serving /verArchivo}}
Traceback (most recent call last):
  File "C:\xampp\htdocs\CLANAD_PY\FlaskSecurity\app\src\Actividad.py", line 408, in ver_archivo_por_codigo
    if not Path(location).is_file():
NameError: name 'Path' is not defined

During handling of the above exception, another exception occurred:

Traceback (most recent call last):
  File "C:\Users\Administrador.WIN-DUOGLHGMSST\AppData\Local\Programs\Python\Python37\lib\site-packages\waitress\channel.py", line 397, in service
    task.service()
  File "C:\Users\Administrador.WIN-DUOGLHGMSST\AppData\Local\Programs\Python\Python37\lib\site-packages\waitress\task.py", line 168, in service
    self.execute()
  File "C:\Users\Administrador.WIN-DUOGLHGMSST\AppData\Local\Programs\Python\Python37\lib\site-packages\waitress\task.py", line 434, in execute
    app_iter = self.channel.server.application(environ, start_response)
  File "C:\Users\Administrador.WIN-DUOGLHGMSST\AppData\Local\Programs\Python\Python37\lib\site-packages\flask\app.py", line 2091, in __call__
    return self.wsgi_app(environ, start_response)
  File "C:\Users\Administrador.WIN-DUOGLHGMSST\AppData\Local\Programs\Python\Python37\lib\site-packages\flask\app.py", line 2076, in wsgi_app
    response = self.handle_exception(e)
  File "C:\Users\Administrador.WIN-DUOGLHGMSST\AppData\Local\Programs\Python\Python37\lib\site-packages\flask\app.py", line 2073, in wsgi_app
    response = self.full_dispatch_request()
  File "C:\Users\Administrador.WIN-DUOGLHGMSST\AppData\Local\Programs\Python\Python37\lib\site-packages\flask\app.py", line 1518, in full_dispatch_request
    rv = self.handle_user_exception(e)
  File "C:\Users\Administrador.WIN-DUOGLHGMSST\AppData\Local\Programs\Python\Python37\lib\site-packages\flask\app.py", line 1516, in full_dispatch_request
    rv = self.dispatch_request()
  File "C:\Users\Administrador.WIN-DUOGLHGMSST\AppData\Local\Programs\Python\Python37\lib\site-packages\flask\app.py", line 1502, in dispatch_request
    return self.ensure_sync(self.view_functions[rule.endpoint])(**req.view_args)
  File "C:\xampp\htdocs\CLANAD_PY\FlaskSecurity\app\src\Actividad.py", line 414, in ver_archivo_por_codigo
    print(e.__class__.__name__)
NameError: name 'e' is not defined
{'TIME':2022-02-04 15:53:31,725,'ADDRESS':'10.10.150.200','URL': 'http://10.10.110.13:8001/verArchivo','TYPE':'ERROR','MODULE':'channel','MSG':{Exception while serving /verArchivo}}
Traceback (most recent call last):
  File "C:\xampp\htdocs\CLANAD_PY\FlaskSecurity\app\src\Actividad.py", line 408, in ver_archivo_por_codigo
    if not Path(location).is_file():
NameError: name 'Path' is not defined

During handling of the above exception, another exception occurred:

Traceback (most recent call last):
  File "C:\Users\Administrador.WIN-DUOGLHGMSST\AppData\Local\Programs\Python\Python37\lib\site-packages\waitress\channel.py", line 397, in service
    task.service()
  File "C:\Users\Administrador.WIN-DUOGLHGMSST\AppData\Local\Programs\Python\Python37\lib\site-packages\waitress\task.py", line 168, in service
    self.execute()
  File "C:\Users\Administrador.WIN-DUOGLHGMSST\AppData\Local\Programs\Python\Python37\lib\site-packages\waitress\task.py", line 434, in execute
    app_iter = self.channel.server.application(environ, start_response)
  File "C:\Users\Administrador.WIN-DUOGLHGMSST\AppData\Local\Programs\Python\Python37\lib\site-packages\flask\app.py", line 2091, in __call__
    return self.wsgi_app(environ, start_response)
  File "C:\Users\Administrador.WIN-DUOGLHGMSST\AppData\Local\Programs\Python\Python37\lib\site-packages\flask\app.py", line 2076, in wsgi_app
    response = self.handle_exception(e)
  File "C:\Users\Administrador.WIN-DUOGLHGMSST\AppData\Local\Programs\Python\Python37\lib\site-packages\flask\app.py", line 2073, in wsgi_app
    response = self.full_dispatch_request()
  File "C:\Users\Administrador.WIN-DUOGLHGMSST\AppData\Local\Programs\Python\Python37\lib\site-packages\flask\app.py", line 1518, in full_dispatch_request
    rv = self.handle_user_exception(e)
  File "C:\Users\Administrador.WIN-DUOGLHGMSST\AppData\Local\Programs\Python\Python37\lib\site-packages\flask\app.py", line 1516, in full_dispatch_request
    rv = self.dispatch_request()
  File "C:\Users\Administrador.WIN-DUOGLHGMSST\AppData\Local\Programs\Python\Python37\lib\site-packages\flask\app.py", line 1502, in dispatch_request
    return self.ensure_sync(self.view_functions[rule.endpoint])(**req.view_args)
  File "C:\xampp\htdocs\CLANAD_PY\FlaskSecurity\app\src\Actividad.py", line 414, in ver_archivo_por_codigo
    print(e.__class__.__name__)
NameError: name 'e' is not defined
{'TIME':2022-02-04 16:03:26,960,'ADDRESS':'127.0.0.1','URL': 'http://localhost:8001/test','TYPE':'ERROR','MODULE':'channel','MSG':{Exception while serving /test}}
Traceback (most recent call last):
  File "C:\xampp\htdocs\CLANAD_PY\FlaskSecurity\app\src\Actividad.py", line 393, in codigo_hash
    raise ValueError("ENCRYPT FALLO")
ValueError: ENCRYPT FALLO

During handling of the above exception, another exception occurred:

Traceback (most recent call last):
  File "C:\Users\Administrador.WIN-DUOGLHGMSST\AppData\Local\Programs\Python\Python37\lib\site-packages\waitress\channel.py", line 397, in service
    task.service()
  File "C:\Users\Administrador.WIN-DUOGLHGMSST\AppData\Local\Programs\Python\Python37\lib\site-packages\waitress\task.py", line 168, in service
    self.execute()
  File "C:\Users\Administrador.WIN-DUOGLHGMSST\AppData\Local\Programs\Python\Python37\lib\site-packages\waitress\task.py", line 434, in execute
    app_iter = self.channel.server.application(environ, start_response)
  File "C:\Users\Administrador.WIN-DUOGLHGMSST\AppData\Local\Programs\Python\Python37\lib\site-packages\flask\app.py", line 2091, in __call__
    return self.wsgi_app(environ, start_response)
  File "C:\Users\Administrador.WIN-DUOGLHGMSST\AppData\Local\Programs\Python\Python37\lib\site-packages\flask\app.py", line 2076, in wsgi_app
    response = self.handle_exception(e)
  File "C:\Users\Administrador.WIN-DUOGLHGMSST\AppData\Local\Programs\Python\Python37\lib\site-packages\flask\app.py", line 2073, in wsgi_app
    response = self.full_dispatch_request()
  File "C:\Users\Administrador.WIN-DUOGLHGMSST\AppData\Local\Programs\Python\Python37\lib\site-packages\flask\app.py", line 1518, in full_dispatch_request
    rv = self.handle_user_exception(e)
  File "C:\Users\Administrador.WIN-DUOGLHGMSST\AppData\Local\Programs\Python\Python37\lib\site-packages\flask\app.py", line 1516, in full_dispatch_request
    rv = self.dispatch_request()
  File "C:\Users\Administrador.WIN-DUOGLHGMSST\AppData\Local\Programs\Python\Python37\lib\site-packages\flask\app.py", line 1502, in dispatch_request
    return self.ensure_sync(self.view_functions[rule.endpoint])(**req.view_args)
  File "C:\xampp\htdocs\CLANAD_PY\FlaskSecurity\app\src\Actividad.py", line 396, in codigo_hash
    print(e.__class__.__name__)
NameError: name 'e' is not defined
{'TIME':2022-02-04 16:05:45,915,'ADDRESS':'10.10.150.200','URL': 'http://10.10.110.13:8001/verArchivo','TYPE':'ERROR','MODULE':'channel','MSG':{Exception while serving /verArchivo}}
Traceback (most recent call last):
  File "C:\xampp\htdocs\CLANAD_PY\FlaskSecurity\app\src\Actividad.py", line 408, in ver_archivo_por_codigo
    if not Path(location).is_file():
NameError: name 'Path' is not defined

During handling of the above exception, another exception occurred:

Traceback (most recent call last):
  File "C:\Users\Administrador.WIN-DUOGLHGMSST\AppData\Local\Programs\Python\Python37\lib\site-packages\waitress\channel.py", line 397, in service
    task.service()
  File "C:\Users\Administrador.WIN-DUOGLHGMSST\AppData\Local\Programs\Python\Python37\lib\site-packages\waitress\task.py", line 168, in service
    self.execute()
  File "C:\Users\Administrador.WIN-DUOGLHGMSST\AppData\Local\Programs\Python\Python37\lib\site-packages\waitress\task.py", line 434, in execute
    app_iter = self.channel.server.application(environ, start_response)
  File "C:\Users\Administrador.WIN-DUOGLHGMSST\AppData\Local\Programs\Python\Python37\lib\site-packages\flask\app.py", line 2091, in __call__
    return self.wsgi_app(environ, start_response)
  File "C:\Users\Administrador.WIN-DUOGLHGMSST\AppData\Local\Programs\Python\Python37\lib\site-packages\flask\app.py", line 2076, in wsgi_app
    response = self.handle_exception(e)
  File "C:\Users\Administrador.WIN-DUOGLHGMSST\AppData\Local\Programs\Python\Python37\lib\site-packages\flask\app.py", line 2073, in wsgi_app
    response = self.full_dispatch_request()
  File "C:\Users\Administrador.WIN-DUOGLHGMSST\AppData\Local\Programs\Python\Python37\lib\site-packages\flask\app.py", line 1518, in full_dispatch_request
    rv = self.handle_user_exception(e)
  File "C:\Users\Administrador.WIN-DUOGLHGMSST\AppData\Local\Programs\Python\Python37\lib\site-packages\flask\app.py", line 1516, in full_dispatch_request
    rv = self.dispatch_request()
  File "C:\Users\Administrador.WIN-DUOGLHGMSST\AppData\Local\Programs\Python\Python37\lib\site-packages\flask\app.py", line 1502, in dispatch_request
    return self.ensure_sync(self.view_functions[rule.endpoint])(**req.view_args)
  File "C:\xampp\htdocs\CLANAD_PY\FlaskSecurity\app\src\Actividad.py", line 414, in ver_archivo_por_codigo
    print(e.__class__.__name__)
NameError: name 'e' is not defined
{'TIME':2022-02-04 16:07:19,240,'ADDRESS':'127.0.0.1','URL': 'http://localhost:8001/test','TYPE':'ERROR','MODULE':'channel','MSG':{Exception while serving /test}}
Traceback (most recent call last):
  File "C:\xampp\htdocs\CLANAD_PY\FlaskSecurity\app\src\Actividad.py", line 393, in codigo_hash
    raise ValueError("ENCRYPT FALLO")
ValueError: ENCRYPT FALLO

During handling of the above exception, another exception occurred:

Traceback (most recent call last):
  File "C:\Users\Administrador.WIN-DUOGLHGMSST\AppData\Local\Programs\Python\Python37\lib\site-packages\waitress\channel.py", line 397, in service
    task.service()
  File "C:\Users\Administrador.WIN-DUOGLHGMSST\AppData\Local\Programs\Python\Python37\lib\site-packages\waitress\task.py", line 168, in service
    self.execute()
  File "C:\Users\Administrador.WIN-DUOGLHGMSST\AppData\Local\Programs\Python\Python37\lib\site-packages\waitress\task.py", line 434, in execute
    app_iter = self.channel.server.application(environ, start_response)
  File "C:\Users\Administrador.WIN-DUOGLHGMSST\AppData\Local\Programs\Python\Python37\lib\site-packages\flask\app.py", line 2091, in __call__
    return self.wsgi_app(environ, start_response)
  File "C:\Users\Administrador.WIN-DUOGLHGMSST\AppData\Local\Programs\Python\Python37\lib\site-packages\flask\app.py", line 2076, in wsgi_app
    response = self.handle_exception(e)
  File "C:\Users\Administrador.WIN-DUOGLHGMSST\AppData\Local\Programs\Python\Python37\lib\site-packages\flask\app.py", line 2073, in wsgi_app
    response = self.full_dispatch_request()
  File "C:\Users\Administrador.WIN-DUOGLHGMSST\AppData\Local\Programs\Python\Python37\lib\site-packages\flask\app.py", line 1518, in full_dispatch_request
    rv = self.handle_user_exception(e)
  File "C:\Users\Administrador.WIN-DUOGLHGMSST\AppData\Local\Programs\Python\Python37\lib\site-packages\flask\app.py", line 1516, in full_dispatch_request
    rv = self.dispatch_request()
  File "C:\Users\Administrador.WIN-DUOGLHGMSST\AppData\Local\Programs\Python\Python37\lib\site-packages\flask\app.py", line 1502, in dispatch_request
    return self.ensure_sync(self.view_functions[rule.endpoint])(**req.view_args)
  File "C:\xampp\htdocs\CLANAD_PY\FlaskSecurity\app\src\Actividad.py", line 396, in codigo_hash
    print(e.__class__.__name__)
NameError: name 'e' is not defined
{'TIME':2022-02-04 16:09:03,345,'ADDRESS':'127.0.0.1','URL': 'http://localhost:8001/test','TYPE':'ERROR','MODULE':'channel','MSG':{Exception while serving /test}}
Traceback (most recent call last):
  File "C:\xampp\htdocs\CLANAD_PY\FlaskSecurity\app\src\Actividad.py", line 393, in codigo_hash
    raise ValueError("ENCRYPT FALLO")
ValueError: ENCRYPT FALLO

During handling of the above exception, another exception occurred:

Traceback (most recent call last):
  File "C:\Users\Administrador.WIN-DUOGLHGMSST\AppData\Local\Programs\Python\Python37\lib\site-packages\waitress\channel.py", line 397, in service
    task.service()
  File "C:\Users\Administrador.WIN-DUOGLHGMSST\AppData\Local\Programs\Python\Python37\lib\site-packages\waitress\task.py", line 168, in service
    self.execute()
  File "C:\Users\Administrador.WIN-DUOGLHGMSST\AppData\Local\Programs\Python\Python37\lib\site-packages\waitress\task.py", line 434, in execute
    app_iter = self.channel.server.application(environ, start_response)
  File "C:\Users\Administrador.WIN-DUOGLHGMSST\AppData\Local\Programs\Python\Python37\lib\site-packages\flask\app.py", line 2091, in __call__
    return self.wsgi_app(environ, start_response)
  File "C:\Users\Administrador.WIN-DUOGLHGMSST\AppData\Local\Programs\Python\Python37\lib\site-packages\flask\app.py", line 2076, in wsgi_app
    response = self.handle_exception(e)
  File "C:\Users\Administrador.WIN-DUOGLHGMSST\AppData\Local\Programs\Python\Python37\lib\site-packages\flask\app.py", line 2073, in wsgi_app
    response = self.full_dispatch_request()
  File "C:\Users\Administrador.WIN-DUOGLHGMSST\AppData\Local\Programs\Python\Python37\lib\site-packages\flask\app.py", line 1518, in full_dispatch_request
    rv = self.handle_user_exception(e)
  File "C:\Users\Administrador.WIN-DUOGLHGMSST\AppData\Local\Programs\Python\Python37\lib\site-packages\flask\app.py", line 1516, in full_dispatch_request
    rv = self.dispatch_request()
  File "C:\Users\Administrador.WIN-DUOGLHGMSST\AppData\Local\Programs\Python\Python37\lib\site-packages\flask\app.py", line 1502, in dispatch_request
    return self.ensure_sync(self.view_functions[rule.endpoint])(**req.view_args)
  File "C:\xampp\htdocs\CLANAD_PY\FlaskSecurity\app\src\Actividad.py", line 396, in codigo_hash
    print(e.__class__.__name__)
NameError: name 'e' is not defined
{'TIME':2022-02-04 16:12:15,728,'ADDRESS':'10.10.150.200','URL': 'http://10.10.110.13:8001/verArchivo','TYPE':'ERROR','MODULE':'channel','MSG':{Exception while serving /verArchivo}}
Traceback (most recent call last):
  File "C:\xampp\htdocs\CLANAD_PY\FlaskSecurity\app\src\Actividad.py", line 408, in ver_archivo_por_codigo
    if not Path(location).is_file():
NameError: name 'Path' is not defined

During handling of the above exception, another exception occurred:

Traceback (most recent call last):
  File "C:\Users\Administrador.WIN-DUOGLHGMSST\AppData\Local\Programs\Python\Python37\lib\site-packages\waitress\channel.py", line 397, in service
    task.service()
  File "C:\Users\Administrador.WIN-DUOGLHGMSST\AppData\Local\Programs\Python\Python37\lib\site-packages\waitress\task.py", line 168, in service
    self.execute()
  File "C:\Users\Administrador.WIN-DUOGLHGMSST\AppData\Local\Programs\Python\Python37\lib\site-packages\waitress\task.py", line 434, in execute
    app_iter = self.channel.server.application(environ, start_response)
  File "C:\Users\Administrador.WIN-DUOGLHGMSST\AppData\Local\Programs\Python\Python37\lib\site-packages\flask\app.py", line 2091, in __call__
    return self.wsgi_app(environ, start_response)
  File "C:\Users\Administrador.WIN-DUOGLHGMSST\AppData\Local\Programs\Python\Python37\lib\site-packages\flask\app.py", line 2076, in wsgi_app
    response = self.handle_exception(e)
  File "C:\Users\Administrador.WIN-DUOGLHGMSST\AppData\Local\Programs\Python\Python37\lib\site-packages\flask\app.py", line 2073, in wsgi_app
    response = self.full_dispatch_request()
  File "C:\Users\Administrador.WIN-DUOGLHGMSST\AppData\Local\Programs\Python\Python37\lib\site-packages\flask\app.py", line 1518, in full_dispatch_request
    rv = self.handle_user_exception(e)
  File "C:\Users\Administrador.WIN-DUOGLHGMSST\AppData\Local\Programs\Python\Python37\lib\site-packages\flask\app.py", line 1516, in full_dispatch_request
    rv = self.dispatch_request()
  File "C:\Users\Administrador.WIN-DUOGLHGMSST\AppData\Local\Programs\Python\Python37\lib\site-packages\flask\app.py", line 1502, in dispatch_request
    return self.ensure_sync(self.view_functions[rule.endpoint])(**req.view_args)
  File "C:\xampp\htdocs\CLANAD_PY\FlaskSecurity\app\src\Actividad.py", line 414, in ver_archivo_por_codigo
    print(e.__class__.__name__)
NameError: name 'e' is not defined
{'TIME':2022-02-04 16:13:38,122,'ADDRESS':'10.10.150.200','URL': 'http://10.10.110.13:8001/verArchivo','TYPE':'ERROR','MODULE':'channel','MSG':{Exception while serving /verArchivo}}
Traceback (most recent call last):
  File "C:\xampp\htdocs\CLANAD_PY\FlaskSecurity\app\src\Actividad.py", line 408, in ver_archivo_por_codigo
    if not Path(location).is_file():
NameError: name 'Path' is not defined

During handling of the above exception, another exception occurred:

Traceback (most recent call last):
  File "C:\Users\Administrador.WIN-DUOGLHGMSST\AppData\Local\Programs\Python\Python37\lib\site-packages\waitress\channel.py", line 397, in service
    task.service()
  File "C:\Users\Administrador.WIN-DUOGLHGMSST\AppData\Local\Programs\Python\Python37\lib\site-packages\waitress\task.py", line 168, in service
    self.execute()
  File "C:\Users\Administrador.WIN-DUOGLHGMSST\AppData\Local\Programs\Python\Python37\lib\site-packages\waitress\task.py", line 434, in execute
    app_iter = self.channel.server.application(environ, start_response)
  File "C:\Users\Administrador.WIN-DUOGLHGMSST\AppData\Local\Programs\Python\Python37\lib\site-packages\flask\app.py", line 2091, in __call__
    return self.wsgi_app(environ, start_response)
  File "C:\Users\Administrador.WIN-DUOGLHGMSST\AppData\Local\Programs\Python\Python37\lib\site-packages\flask\app.py", line 2076, in wsgi_app
    response = self.handle_exception(e)
  File "C:\Users\Administrador.WIN-DUOGLHGMSST\AppData\Local\Programs\Python\Python37\lib\site-packages\flask\app.py", line 2073, in wsgi_app
    response = self.full_dispatch_request()
  File "C:\Users\Administrador.WIN-DUOGLHGMSST\AppData\Local\Programs\Python\Python37\lib\site-packages\flask\app.py", line 1518, in full_dispatch_request
    rv = self.handle_user_exception(e)
  File "C:\Users\Administrador.WIN-DUOGLHGMSST\AppData\Local\Programs\Python\Python37\lib\site-packages\flask\app.py", line 1516, in full_dispatch_request
    rv = self.dispatch_request()
  File "C:\Users\Administrador.WIN-DUOGLHGMSST\AppData\Local\Programs\Python\Python37\lib\site-packages\flask\app.py", line 1502, in dispatch_request
    return self.ensure_sync(self.view_functions[rule.endpoint])(**req.view_args)
  File "C:\xampp\htdocs\CLANAD_PY\FlaskSecurity\app\src\Actividad.py", line 414, in ver_archivo_por_codigo
    print(e.__class__.__name__)
NameError: name 'e' is not defined
{'TIME':2022-02-04 16:20:47,564,'ADDRESS':'10.10.150.200','URL': 'http://10.10.110.13:8001/verArchivo','TYPE':'ERROR','MODULE':'channel','MSG':{Exception while serving /verArchivo}}
Traceback (most recent call last):
  File "C:\xampp\htdocs\CLANAD_PY\FlaskSecurity\app\src\Actividad.py", line 407, in ver_archivo_por_codigo
    if not Path(location).is_file():
NameError: name 'Path' is not defined

During handling of the above exception, another exception occurred:

Traceback (most recent call last):
  File "C:\Users\Administrador.WIN-DUOGLHGMSST\AppData\Local\Programs\Python\Python37\lib\site-packages\waitress\channel.py", line 397, in service
    task.service()
  File "C:\Users\Administrador.WIN-DUOGLHGMSST\AppData\Local\Programs\Python\Python37\lib\site-packages\waitress\task.py", line 168, in service
    self.execute()
  File "C:\Users\Administrador.WIN-DUOGLHGMSST\AppData\Local\Programs\Python\Python37\lib\site-packages\waitress\task.py", line 434, in execute
    app_iter = self.channel.server.application(environ, start_response)
  File "C:\Users\Administrador.WIN-DUOGLHGMSST\AppData\Local\Programs\Python\Python37\lib\site-packages\flask\app.py", line 2091, in __call__
    return self.wsgi_app(environ, start_response)
  File "C:\Users\Administrador.WIN-DUOGLHGMSST\AppData\Local\Programs\Python\Python37\lib\site-packages\flask\app.py", line 2076, in wsgi_app
    response = self.handle_exception(e)
  File "C:\Users\Administrador.WIN-DUOGLHGMSST\AppData\Local\Programs\Python\Python37\lib\site-packages\flask\app.py", line 2073, in wsgi_app
    response = self.full_dispatch_request()
  File "C:\Users\Administrador.WIN-DUOGLHGMSST\AppData\Local\Programs\Python\Python37\lib\site-packages\flask\app.py", line 1518, in full_dispatch_request
    rv = self.handle_user_exception(e)
  File "C:\Users\Administrador.WIN-DUOGLHGMSST\AppData\Local\Programs\Python\Python37\lib\site-packages\flask\app.py", line 1516, in full_dispatch_request
    rv = self.dispatch_request()
  File "C:\Users\Administrador.WIN-DUOGLHGMSST\AppData\Local\Programs\Python\Python37\lib\site-packages\flask\app.py", line 1502, in dispatch_request
    return self.ensure_sync(self.view_functions[rule.endpoint])(**req.view_args)
  File "C:\xampp\htdocs\CLANAD_PY\FlaskSecurity\app\src\Actividad.py", line 413, in ver_archivo_por_codigo
    print(e.__class__.__name__)
NameError: name 'e' is not defined
{'TIME':2022-02-04 16:22:44,753,'ADDRESS':'10.10.150.200','URL': 'http://10.10.110.13:8001/verArchivo','TYPE':'ERROR','MODULE':'channel','MSG':{Exception while serving /verArchivo}}
Traceback (most recent call last):
  File "C:\xampp\htdocs\CLANAD_PY\FlaskSecurity\app\src\Actividad.py", line 407, in ver_archivo_por_codigo
    if not Path(location).is_file():
NameError: name 'Path' is not defined

During handling of the above exception, another exception occurred:

Traceback (most recent call last):
  File "C:\Users\Administrador.WIN-DUOGLHGMSST\AppData\Local\Programs\Python\Python37\lib\site-packages\waitress\channel.py", line 397, in service
    task.service()
  File "C:\Users\Administrador.WIN-DUOGLHGMSST\AppData\Local\Programs\Python\Python37\lib\site-packages\waitress\task.py", line 168, in service
    self.execute()
  File "C:\Users\Administrador.WIN-DUOGLHGMSST\AppData\Local\Programs\Python\Python37\lib\site-packages\waitress\task.py", line 434, in execute
    app_iter = self.channel.server.application(environ, start_response)
  File "C:\Users\Administrador.WIN-DUOGLHGMSST\AppData\Local\Programs\Python\Python37\lib\site-packages\flask\app.py", line 2091, in __call__
    return self.wsgi_app(environ, start_response)
  File "C:\Users\Administrador.WIN-DUOGLHGMSST\AppData\Local\Programs\Python\Python37\lib\site-packages\flask\app.py", line 2076, in wsgi_app
    response = self.handle_exception(e)
  File "C:\Users\Administrador.WIN-DUOGLHGMSST\AppData\Local\Programs\Python\Python37\lib\site-packages\flask\app.py", line 2073, in wsgi_app
    response = self.full_dispatch_request()
  File "C:\Users\Administrador.WIN-DUOGLHGMSST\AppData\Local\Programs\Python\Python37\lib\site-packages\flask\app.py", line 1518, in full_dispatch_request
    rv = self.handle_user_exception(e)
  File "C:\Users\Administrador.WIN-DUOGLHGMSST\AppData\Local\Programs\Python\Python37\lib\site-packages\flask\app.py", line 1516, in full_dispatch_request
    rv = self.dispatch_request()
  File "C:\Users\Administrador.WIN-DUOGLHGMSST\AppData\Local\Programs\Python\Python37\lib\site-packages\flask\app.py", line 1502, in dispatch_request
    return self.ensure_sync(self.view_functions[rule.endpoint])(**req.view_args)
  File "C:\xampp\htdocs\CLANAD_PY\FlaskSecurity\app\src\Actividad.py", line 416, in ver_archivo_por_codigo
    print(e.__class__.__name__)
NameError: name 'e' is not defined
{'TIME':2022-02-04 16:24:03,241,'ADDRESS':'10.10.150.200','URL': 'http://10.10.110.13:8001/verArchivo','TYPE':'ERROR','MODULE':'channel','MSG':{Exception while serving /verArchivo}}
Traceback (most recent call last):
  File "C:\xampp\htdocs\CLANAD_PY\FlaskSecurity\app\src\Actividad.py", line 416, in ver_archivo_por_codigo
    return jsonify(blob), 200
  File "C:\Users\Administrador.WIN-DUOGLHGMSST\AppData\Local\Programs\Python\Python37\lib\site-packages\flask\json\__init__.py", line 355, in jsonify
    f"{dumps(data, indent=indent, separators=separators)}\n",
  File "C:\Users\Administrador.WIN-DUOGLHGMSST\AppData\Local\Programs\Python\Python37\lib\site-packages\flask\json\__init__.py", line 133, in dumps
    rv = _json.dumps(obj, **kwargs)
  File "C:\Users\Administrador.WIN-DUOGLHGMSST\AppData\Local\Programs\Python\Python37\lib\json\__init__.py", line 238, in dumps
    **kw).encode(obj)
  File "C:\Users\Administrador.WIN-DUOGLHGMSST\AppData\Local\Programs\Python\Python37\lib\json\encoder.py", line 201, in encode
    chunks = list(chunks)
  File "C:\Users\Administrador.WIN-DUOGLHGMSST\AppData\Local\Programs\Python\Python37\lib\json\encoder.py", line 438, in _iterencode
    o = _default(o)
  File "C:\Users\Administrador.WIN-DUOGLHGMSST\AppData\Local\Programs\Python\Python37\lib\site-packages\flask\json\__init__.py", line 57, in default
    return super().default(o)
  File "C:\Users\Administrador.WIN-DUOGLHGMSST\AppData\Local\Programs\Python\Python37\lib\json\encoder.py", line 179, in default
    raise TypeError(f'Object of type {o.__class__.__name__} '
TypeError: Object of type bytes is not JSON serializable

During handling of the above exception, another exception occurred:

Traceback (most recent call last):
  File "C:\Users\Administrador.WIN-DUOGLHGMSST\AppData\Local\Programs\Python\Python37\lib\site-packages\waitress\channel.py", line 397, in service
    task.service()
  File "C:\Users\Administrador.WIN-DUOGLHGMSST\AppData\Local\Programs\Python\Python37\lib\site-packages\waitress\task.py", line 168, in service
    self.execute()
  File "C:\Users\Administrador.WIN-DUOGLHGMSST\AppData\Local\Programs\Python\Python37\lib\site-packages\waitress\task.py", line 434, in execute
    app_iter = self.channel.server.application(environ, start_response)
  File "C:\Users\Administrador.WIN-DUOGLHGMSST\AppData\Local\Programs\Python\Python37\lib\site-packages\flask\app.py", line 2091, in __call__
    return self.wsgi_app(environ, start_response)
  File "C:\Users\Administrador.WIN-DUOGLHGMSST\AppData\Local\Programs\Python\Python37\lib\site-packages\flask\app.py", line 2076, in wsgi_app
    response = self.handle_exception(e)
  File "C:\Users\Administrador.WIN-DUOGLHGMSST\AppData\Local\Programs\Python\Python37\lib\site-packages\flask\app.py", line 2073, in wsgi_app
    response = self.full_dispatch_request()
  File "C:\Users\Administrador.WIN-DUOGLHGMSST\AppData\Local\Programs\Python\Python37\lib\site-packages\flask\app.py", line 1518, in full_dispatch_request
    rv = self.handle_user_exception(e)
  File "C:\Users\Administrador.WIN-DUOGLHGMSST\AppData\Local\Programs\Python\Python37\lib\site-packages\flask\app.py", line 1516, in full_dispatch_request
    rv = self.dispatch_request()
  File "C:\Users\Administrador.WIN-DUOGLHGMSST\AppData\Local\Programs\Python\Python37\lib\site-packages\flask\app.py", line 1502, in dispatch_request
    return self.ensure_sync(self.view_functions[rule.endpoint])(**req.view_args)
  File "C:\xampp\htdocs\CLANAD_PY\FlaskSecurity\app\src\Actividad.py", line 418, in ver_archivo_por_codigo
    print(e.__class__.__name__)
NameError: name 'e' is not defined
{'TIME':2022-02-04 16:35:48,432,'ADDRESS':'10.10.150.200','URL': 'http://10.10.110.13:8001/verArchivo','TYPE':'ERROR','MODULE':'channel','MSG':{Exception while serving /verArchivo}}
Traceback (most recent call last):
  File "C:\xampp\htdocs\CLANAD_PY\FlaskSecurity\app\src\Actividad.py", line 414, in ver_archivo_por_codigo
    return jsonify(loblob), 200
  File "C:\Users\Administrador.WIN-DUOGLHGMSST\AppData\Local\Programs\Python\Python37\lib\site-packages\flask\json\__init__.py", line 355, in jsonify
    f"{dumps(data, indent=indent, separators=separators)}\n",
  File "C:\Users\Administrador.WIN-DUOGLHGMSST\AppData\Local\Programs\Python\Python37\lib\site-packages\flask\json\__init__.py", line 133, in dumps
    rv = _json.dumps(obj, **kwargs)
  File "C:\Users\Administrador.WIN-DUOGLHGMSST\AppData\Local\Programs\Python\Python37\lib\json\__init__.py", line 238, in dumps
    **kw).encode(obj)
  File "C:\Users\Administrador.WIN-DUOGLHGMSST\AppData\Local\Programs\Python\Python37\lib\json\encoder.py", line 201, in encode
    chunks = list(chunks)
  File "C:\Users\Administrador.WIN-DUOGLHGMSST\AppData\Local\Programs\Python\Python37\lib\json\encoder.py", line 438, in _iterencode
    o = _default(o)
  File "C:\Users\Administrador.WIN-DUOGLHGMSST\AppData\Local\Programs\Python\Python37\lib\site-packages\flask\json\__init__.py", line 57, in default
    return super().default(o)
  File "C:\Users\Administrador.WIN-DUOGLHGMSST\AppData\Local\Programs\Python\Python37\lib\json\encoder.py", line 179, in default
    raise TypeError(f'Object of type {o.__class__.__name__} '
TypeError: Object of type bytes is not JSON serializable

During handling of the above exception, another exception occurred:

Traceback (most recent call last):
  File "C:\Users\Administrador.WIN-DUOGLHGMSST\AppData\Local\Programs\Python\Python37\lib\site-packages\waitress\channel.py", line 397, in service
    task.service()
  File "C:\Users\Administrador.WIN-DUOGLHGMSST\AppData\Local\Programs\Python\Python37\lib\site-packages\waitress\task.py", line 168, in service
    self.execute()
  File "C:\Users\Administrador.WIN-DUOGLHGMSST\AppData\Local\Programs\Python\Python37\lib\site-packages\waitress\task.py", line 434, in execute
    app_iter = self.channel.server.application(environ, start_response)
  File "C:\Users\Administrador.WIN-DUOGLHGMSST\AppData\Local\Programs\Python\Python37\lib\site-packages\flask\app.py", line 2091, in __call__
    return self.wsgi_app(environ, start_response)
  File "C:\Users\Administrador.WIN-DUOGLHGMSST\AppData\Local\Programs\Python\Python37\lib\site-packages\flask\app.py", line 2076, in wsgi_app
    response = self.handle_exception(e)
  File "C:\Users\Administrador.WIN-DUOGLHGMSST\AppData\Local\Programs\Python\Python37\lib\site-packages\flask\app.py", line 2073, in wsgi_app
    response = self.full_dispatch_request()
  File "C:\Users\Administrador.WIN-DUOGLHGMSST\AppData\Local\Programs\Python\Python37\lib\site-packages\flask\app.py", line 1518, in full_dispatch_request
    rv = self.handle_user_exception(e)
  File "C:\Users\Administrador.WIN-DUOGLHGMSST\AppData\Local\Programs\Python\Python37\lib\site-packages\flask\app.py", line 1516, in full_dispatch_request
    rv = self.dispatch_request()
  File "C:\Users\Administrador.WIN-DUOGLHGMSST\AppData\Local\Programs\Python\Python37\lib\site-packages\flask\app.py", line 1502, in dispatch_request
    return self.ensure_sync(self.view_functions[rule.endpoint])(**req.view_args)
  File "C:\xampp\htdocs\CLANAD_PY\FlaskSecurity\app\src\Actividad.py", line 416, in ver_archivo_por_codigo
    print(e.__class__.__name__)
NameError: name 'e' is not defined
